Workbook

Sheet Cash Flow
A1: Year-by-Year Cash Flow with T1032 Income Splitting
A2: Real 2026 $. Split = equalize the two taxable incomes, capped at 50% of Alec’s eligible pension (LAPP + RRIF). Columns W/X/Y show the benefit vs. not splitting. Tax = bracket estimate, confirm with accountant.
A4: Year | B4: Alec age | C4: Andrea age | D4: Alec LAPP | E4: Alec CPP | F4: Alec OAS | G4: Alec RRIF w/d | H4: Alec pre-split | I4: Andrea LAPP | J4: Andrea CPP | K4: Andrea OAS | L4: Andrea RRIF w/d | M4: Andrea pre-split | N4: Alec elig. pension | O4: Split A→An | P4: Alec post-split | Q4: Andrea post-split | R4: Alec tax | S4: Andrea tax | T4: Alec clawbk | U4: Andrea clawbk | V4: H/H after-tax | W4: Tax+CB WITH split | X4: Tax+CB NO split | Y4: Split SAVING
A5: 2030 | B5: =A5-Assumptions!$B$29 -> 65 | C5: =A5-Assumptions!$B$30 -> 62 | D5: =IF(A5>=Assumptions!$B$23,Assumptions!$B$13*(1+Assumptions!$B$6)^(A5-Assumptions!$B$23),0) -> 67700 | E5: =IF(A5>=Assumptions!$B$24,Assumptions!$B$15,0) -> 0 | F5: =IF(A5>=Assumptions!$B$23,Assumptions!$B$17,0) -> 8917 | G5: =MIN(Z5,MAX(IF(AND(A5>=2030,A5<=2034),Assumptions!$B$32,0),IF(B5<71,0,VLOOKUP(MIN(B5,95),Assumptions!$E$37:$F$61,2,TRUE()))*Z5)) -> 25000 | H5: =D5+E5+F5+G5 -> 101617 | I5: =IF(A5>=Assumptions!$B$26,Assumptions!$B$14*(1+Assumptions!$B$6)^(A5-Assumptions!$B$26),0) -> 47480 | J5: =IF(A5>=Assumptions!$B$27,Assumptions!$B$16,0) -> 0 | K5: =IF(A5>=Assumptions!$B$27,Assumptions!$B$18,0) -> 0 | L5: =MIN(AA5,IF(C5<71,0,VLOOKUP(MIN(C5,95),Assumptions!$E$37:$F$61,2,TRUE()))*AA5) -> 0 | M5: =I5+J5+K5+L5 -> 47480 | N5: =D5+G5 -> 92700 | O5: =MIN(0.5*N5,MAX(0,(H5-M5)/2)) -> 27068.5 | P5: =H5-O5 -> 74548.5 | Q5: =M5+O5 -> 74548.5 | R5: =SUMPRODUCT(Assumptions!$B$36:$B$42,(P5-Assumptions!$A$36:$A$42)*((P5-Assumptions!$A$36:$A$42)>0)) -> 13551.667 | S5: =SUMPRODUCT(Assumptions!$B$36:$B$42,(Q5-Assumptions!$A$36:$A$42)*((Q5-Assumptions!$A$36:$A$42)>0)) -> 13551.667 | T5: =IF(B5>=65,MIN(F5,Assumptions!$B$9*MAX(0,P5-Assumptions!$B$8)),0) -> 0 | U5: =IF(C5>=65,MIN(K5,Assumptions!$B$9*MAX(0,Q5-Assumptions!$B$8)),0) -> 0 | V5: =H5+M5-R5-S5-T5-U5 -> 121993.66 | W5: =R5+S5+T5+U5 -> 27103.335 | X5: =SUMPRODUCT(Assumptions!$B$36:$B$42,(H5-Assumptions!$A$36:$A$42)*((H5-Assumptions!$A$36:$A$42)>0))+SUMPRODUCT(Assumptions!$B$36:$B$42,(M5-Assumptions!$A$36:$A$42)*((M5-Assumptions!$A$36:$A$42)>0))+IF(B5>=65,MIN(F5,Assumptions!$B$9*MAX(0,H5-Assumptions!$B$8)),0)+IF(C5>=65,MIN(K5,Assumptions!$B$9*MAX(0,M5-Assumptions!$B$8)),0) -> 28842.06 | Y5: =X5-W5 -> 1738.725 | Z5: =Assumptions!$B$19*(1+Assumptions!$B$7)^(A5-2026) -> 225101.76 | AA5: =Assumptions!$B$20*(1+Assumptions!$B$7)^(A5-2026) -> 309514.92
A6: 2031 | B6: =A6-Assumptions!$B$29 -> 66 | C6: =A6-Assumptions!$B$30 -> 63 | D6: =IF(A6>=Assumptions!$B$23,Assumptions!$B$13*(1+Assumptions!$B$6)^(A6-Assumptions!$B$23),0) -> 67023 | E6: =IF(A6>=Assumptions!$B$24,Assumptions!$B$15,0) -> 0 | F6: =IF(A6>=Assumptions!$B$23,Assumptions!$B$17,0) -> 8917 | G6: =MIN(Z6,MAX(IF(AND(A6>=2030,A6<=2034),Assumptions!$B$32,0),IF(B6<71,0,VLOOKUP(MIN(B6,95),Assumptions!$E$37:$F$61,2,TRUE()))*Z6)) -> 25000 | H6: =D6+E6+F6+G6 -> 100940 | I6: =IF(A6>=Assumptions!$B$26,Assumptions!$B$14*(1+Assumptions!$B$6)^(A6-Assumptions!$B$26),0) -> 47005.2 | J6: =IF(A6>=Assumptions!$B$27,Assumptions!$B$16,0) -> 0 | K6: =IF(A6>=Assumptions!$B$27,Assumptions!$B$18,0) -> 0 | L6: =MIN(AA6,IF(C6<71,0,VLOOKUP(MIN(C6,95),Assumptions!$E$37:$F$61,2,TRUE()))*AA6) -> 0 | M6: =I6+J6+K6+L6 -> 47005.2 | N6: =D6+G6 -> 92023 | O6: =MIN(0.5*N6,MAX(0,(H6-M6)/2)) -> 26967.4 | P6: =H6-O6 -> 73972.6 | Q6: =M6+O6 -> 73972.6 | R6: =SUMPRODUCT(Assumptions!$B$36:$B$42,(P6-Assumptions!$A$36:$A$42)*((P6-Assumptions!$A$36:$A$42)>0)) -> 13376.018 | S6: =SUMPRODUCT(Assumptions!$B$36:$B$42,(Q6-Assumptions!$A$36:$A$42)*((Q6-Assumptions!$A$36:$A$42)>0)) -> 13376.018 | T6: =IF(B6>=65,MIN(F6,Assumptions!$B$9*MAX(0,P6-Assumptions!$B$8)),0) -> 0 | U6: =IF(C6>=65,MIN(K6,Assumptions!$B$9*MAX(0,Q6-Assumptions!$B$8)),0) -> 0 | V6: =H6+M6-R6-S6-T6-U6 -> 121193.16 | W6: =R6+S6+T6+U6 -> 26752.036 | X6: =SUMPRODUCT(Assumptions!$B$36:$B$42,(H6-Assumptions!$A$36:$A$42)*((H6-Assumptions!$A$36:$A$42)>0))+SUMPRODUCT(Assumptions!$B$36:$B$42,(M6-Assumptions!$A$36:$A$42)*((M6-Assumptions!$A$36:$A$42)>0))+IF(B6>=65,MIN(F6,Assumptions!$B$9*MAX(0,H6-Assumptions!$B$8)),0)+IF(C6>=65,MIN(K6,Assumptions!$B$9*MAX(0,M6-Assumptions!$B$8)),0) -> 28424.821 | Y6: =X6-W6 -> 1672.785 | Z6: =(Z5-G5)*(1+Assumptions!$B$7) -> 206104.81 | AA6: =(AA5-L5)*(1+Assumptions!$B$7) -> 318800.37
A7: 2032 | B7: =A7-Assumptions!$B$29 -> 67 | C7: =A7-Assumptions!$B$30 -> 64 | D7: =IF(A7>=Assumptions!$B$23,Assumptions!$B$13*(1+Assumptions!$B$6)^(A7-Assumptions!$B$23),0) -> 66352.77 | E7: =IF(A7>=Assumptions!$B$24,Assumptions!$B$15,0) -> 0 | F7: =IF(A7>=Assumptions!$B$23,Assumptions!$B$17,0) -> 8917 | G7: =MIN(Z7,MAX(IF(AND(A7>=2030,A7<=2034),Assumptions!$B$32,0),IF(B7<71,0,VLOOKUP(MIN(B7,95),Assumptions!$E$37:$F$61,2,TRUE()))*Z7)) -> 25000 | H7: =D7+E7+F7+G7 -> 100269.77 | I7: =IF(A7>=Assumptions!$B$26,Assumptions!$B$14*(1+Assumptions!$B$6)^(A7-Assumptions!$B$26),0) -> 46535.148 | J7: =IF(A7>=Assumptions!$B$27,Assumptions!$B$16,0) -> 0 | K7: =IF(A7>=Assumptions!$B$27,Assumptions!$B$18,0) -> 0 | L7: =MIN(AA7,IF(C7<71,0,VLOOKUP(MIN(C7,95),Assumptions!$E$37:$F$61,2,TRUE()))*AA7) -> 0 | M7: =I7+J7+K7+L7 -> 46535.148 | N7: =D7+G7 -> 91352.77 | O7: =MIN(0.5*N7,MAX(0,(H7-M7)/2)) -> 26867.311 | P7: =H7-O7 -> 73402.459 | Q7: =M7+O7 -> 73402.459 | R7: =SUMPRODUCT(Assumptions!$B$36:$B$42,(P7-Assumptions!$A$36:$A$42)*((P7-Assumptions!$A$36:$A$42)>0)) -> 13202.125 | S7: =SUMPRODUCT(Assumptions!$B$36:$B$42,(Q7-Assumptions!$A$36:$A$42)*((Q7-Assumptions!$A$36:$A$42)>0)) -> 13202.125 | T7: =IF(B7>=65,MIN(F7,Assumptions!$B$9*MAX(0,P7-Assumptions!$B$8)),0) -> 0 | U7: =IF(C7>=65,MIN(K7,Assumptions!$B$9*MAX(0,Q7-Assumptions!$B$8)),0) -> 0 | V7: =H7+M7-R7-S7-T7-U7 -> 120400.67 | W7: =R7+S7+T7+U7 -> 26404.25 | X7: =SUMPRODUCT(Assumptions!$B$36:$B$42,(H7-Assumptions!$A$36:$A$42)*((H7-Assumptions!$A$36:$A$42)>0))+SUMPRODUCT(Assumptions!$B$36:$B$42,(M7-Assumptions!$A$36:$A$42)*((M7-Assumptions!$A$36:$A$42)>0))+IF(B7>=65,MIN(F7,Assumptions!$B$9*MAX(0,H7-Assumptions!$B$8)),0)+IF(C7>=65,MIN(K7,Assumptions!$B$9*MAX(0,M7-Assumptions!$B$8)),0) -> 28011.754 | Y7: =X7-W7 -> 1607.5044 | Z7: =(Z6-G6)*(1+Assumptions!$B$7) -> 186537.96 | AA7: =(AA6-L6)*(1+Assumptions!$B$7) -> 328364.38
A8: 2033 | B8: =A8-Assumptions!$B$29 -> 68 | C8: =A8-Assumptions!$B$30 -> 65 | D8: =IF(A8>=Assumptions!$B$23,Assumptions!$B$13*(1+Assumptions!$B$6)^(A8-Assumptions!$B$23),0) -> 65689.242 | E8: =IF(A8>=Assumptions!$B$24,Assumptions!$B$15,0) -> 0 | F8: =IF(A8>=Assumptions!$B$23,Assumptions!$B$17,0) -> 8917 | G8: =MIN(Z8,MAX(IF(AND(A8>=2030,A8<=2034),Assumptions!$B$32,0),IF(B8<71,0,VLOOKUP(MIN(B8,95),Assumptions!$E$37:$F$61,2,TRUE()))*Z8)) -> 25000 | H8: =D8+E8+F8+G8 -> 99606.242 | I8: =IF(A8>=Assumptions!$B$26,Assumptions!$B$14*(1+Assumptions!$B$6)^(A8-Assumptions!$B$26),0) -> 46069.797 | J8: =IF(A8>=Assumptions!$B$27,Assumptions!$B$16,0) -> 17185 | K8: =IF(A8>=Assumptions!$B$27,Assumptions!$B$18,0) -> 8917 | L8: =MIN(AA8,IF(C8<71,0,VLOOKUP(MIN(C8,95),Assumptions!$E$37:$F$61,2,TRUE()))*AA8) -> 0 | M8: =I8+J8+K8+L8 -> 72171.797 | N8: =D8+G8 -> 90689.242 | O8: =MIN(0.5*N8,MAX(0,(H8-M8)/2)) -> 13717.223 | P8: =H8-O8 -> 85889.019 | Q8: =M8+O8 -> 85889.019 | R8: =SUMPRODUCT(Assumptions!$B$36:$B$42,(P8-Assumptions!$A$36:$A$42)*((P8-Assumptions!$A$36:$A$42)>0)) -> 17010.526 | S8: =SUMPRODUCT(Assumptions!$B$36:$B$42,(Q8-Assumptions!$A$36:$A$42)*((Q8-Assumptions!$A$36:$A$42)>0)) -> 17010.526 | T8: =IF(B8>=65,MIN(F8,Assumptions!$B$9*MAX(0,P8-Assumptions!$B$8)),0) -> 0 | U8: =IF(C8>=65,MIN(K8,Assumptions!$B$9*MAX(0,Q8-Assumptions!$B$8)),0) -> 0 | V8: =H8+M8-R8-S8-T8-U8 -> 137756.99 | W8: =R8+S8+T8+U8 -> 34021.052 | X8: =SUMPRODUCT(Assumptions!$B$36:$B$42,(H8-Assumptions!$A$36:$A$42)*((H8-Assumptions!$A$36:$A$42)>0))+SUMPRODUCT(Assumptions!$B$36:$B$42,(M8-Assumptions!$A$36:$A$42)*((M8-Assumptions!$A$36:$A$42)>0))+IF(B8>=65,MIN(F8,Assumptions!$B$9*MAX(0,H8-Assumptions!$B$8)),0)+IF(C8>=65,MIN(K8,Assumptions!$B$9*MAX(0,M8-Assumptions!$B$8)),0) -> 34663.538 | Y8: =X8-W8 -> 642.48634 | Z8: =(Z7-G7)*(1+Assumptions!$B$7) -> 166384.1 | AA8: =(AA7-L7)*(1+Assumptions!$B$7) -> 338215.31
A9: 2034 | B9: =A9-Assumptions!$B$29 -> 69 | C9: =A9-Assumptions!$B$30 -> 66 | D9: =IF(A9>=Assumptions!$B$23,Assumptions!$B$13*(1+Assumptions!$B$6)^(A9-Assumptions!$B$23),0) -> 65032.35 | E9: =IF(A9>=Assumptions!$B$24,Assumptions!$B$15,0) -> 0 | F9: =IF(A9>=Assumptions!$B$23,Assumptions!$B$17,0) -> 8917 | G9: =MIN(Z9,MAX(IF(AND(A9>=2030,A9<=2034),Assumptions!$B$32,0),IF(B9<71,0,VLOOKUP(MIN(B9,95),Assumptions!$E$37:$F$61,2,TRUE()))*Z9)) -> 25000 | H9: =D9+E9+F9+G9 -> 98949.35 | I9: =IF(A9>=Assumptions!$B$26,Assumptions!$B$14*(1+Assumptions!$B$6)^(A9-Assumptions!$B$26),0) -> 45609.099 | J9: =IF(A9>=Assumptions!$B$27,Assumptions!$B$16,0) -> 17185 | K9: =IF(A9>=Assumptions!$B$27,Assumptions!$B$18,0) -> 8917 | L9: =MIN(AA9,IF(C9<71,0,VLOOKUP(MIN(C9,95),Assumptions!$E$37:$F$61,2,TRUE()))*AA9) -> 0 | M9: =I9+J9+K9+L9 -> 71711.099 | N9: =D9+G9 -> 90032.35 | O9: =MIN(0.5*N9,MAX(0,(H9-M9)/2)) -> 13619.126 | P9: =H9-O9 -> 85330.224 | Q9: =M9+O9 -> 85330.224 | R9: =SUMPRODUCT(Assumptions!$B$36:$B$42,(P9-Assumptions!$A$36:$A$42)*((P9-Assumptions!$A$36:$A$42)>0)) -> 16840.093 | S9: =SUMPRODUCT(Assumptions!$B$36:$B$42,(Q9-Assumptions!$A$36:$A$42)*((Q9-Assumptions!$A$36:$A$42)>0)) -> 16840.093 | T9: =IF(B9>=65,MIN(F9,Assumptions!$B$9*MAX(0,P9-Assumptions!$B$8)),0) -> 0 | U9: =IF(C9>=65,MIN(K9,Assumptions!$B$9*MAX(0,Q9-Assumptions!$B$8)),0) -> 0 | V9: =H9+M9-R9-S9-T9-U9 -> 136980.26 | W9: =R9+S9+T9+U9 -> 33680.187 | X9: =SUMPRODUCT(Assumptions!$B$36:$B$42,(H9-Assumptions!$A$36:$A$42)*((H9-Assumptions!$A$36:$A$42)>0))+SUMPRODUCT(Assumptions!$B$36:$B$42,(M9-Assumptions!$A$36:$A$42)*((M9-Assumptions!$A$36:$A$42)>0))+IF(B9>=65,MIN(F9,Assumptions!$B$9*MAX(0,H9-Assumptions!$B$8)),0)+IF(C9>=65,MIN(K9,Assumptions!$B$9*MAX(0,M9-Assumptions!$B$8)),0) -> 34224.139 | Y9: =X9-W9 -> 543.95248 | Z9: =(Z8-G8)*(1+Assumptions!$B$7) -> 145625.62 | AA9: =(AA8-L8)*(1+Assumptions!$B$7) -> 348361.77
A10: 2035 | B10: =A10-Assumptions!$B$29 -> 70 | C10: =A10-Assumptions!$B$30 -> 67 | D10: =IF(A10>=Assumptions!$B$23,Assumptions!$B$13*(1+Assumptions!$B$6)^(A10-Assumptions!$B$23),0) -> 64382.026 | E10: =IF(A10>=Assumptions!$B$24,Assumptions!$B$15,0) -> 25690 | F10: =IF(A10>=Assumptions!$B$23,Assumptions!$B$17,0) -> 8917 | G10: =MIN(Z10,MAX(IF(AND(A10>=2030,A10<=2034),Assumptions!$B$32,0),IF(B10<71,0,VLOOKUP(MIN(B10,95),Assumptions!$E$37:$F$61,2,TRUE()))*Z10)) -> 0 | H10: =D10+E10+F10+G10 -> 98989.026 | I10: =IF(A10>=Assumptions!$B$26,Assumptions!$B$14*(1+Assumptions!$B$6)^(A10-Assumptions!$B$26),0) -> 45153.008 | J10: =IF(A10>=Assumptions!$B$27,Assumptions!$B$16,0) -> 17185 | K10: =IF(A10>=Assumptions!$B$27,Assumptions!$B$18,0) -> 8917 | L10: =MIN(AA10,IF(C10<71,0,VLOOKUP(MIN(C10,95),Assumptions!$E$37:$F$61,2,TRUE()))*AA10) -> 0 | M10: =I10+J10+K10+L10 -> 71255.008 | N10: =D10+G10 -> 64382.026 | O10: =MIN(0.5*N10,MAX(0,(H10-M10)/2)) -> 13867.009 | P10: =H10-O10 -> 85122.017 | Q10: =M10+O10 -> 85122.017 | R10: =SUMPRODUCT(Assumptions!$B$36:$B$42,(P10-Assumptions!$A$36:$A$42)*((P10-Assumptions!$A$36:$A$42)>0)) -> 16776.59 | S10: =SUMPRODUCT(Assumptions!$B$36:$B$42,(Q10-Assumptions!$A$36:$A$42)*((Q10-Assumptions!$A$36:$A$42)>0)) -> 16776.59 | T10: =IF(B10>=65,MIN(F10,Assumptions!$B$9*MAX(0,P10-Assumptions!$B$8)),0) -> 0 | U10: =IF(C10>=65,MIN(K10,Assumptions!$B$9*MAX(0,Q10-Assumptions!$B$8)),0) -> 0 | V10: =H10+M10-R10-S10-T10-U10 -> 136690.85 | W10: =R10+S10+T10+U10 -> 33553.18 | X10: =SUMPRODUCT(Assumptions!$B$36:$B$42,(H10-Assumptions!$A$36:$A$42)*((H10-Assumptions!$A$36:$A$42)>0))+SUMPRODUCT(Assumptions!$B$36:$B$42,(M10-Assumptions!$A$36:$A$42)*((M10-Assumptions!$A$36:$A$42)>0))+IF(B10>=65,MIN(F10,Assumptions!$B$9*MAX(0,H10-Assumptions!$B$8)),0)+IF(C10>=65,MIN(K10,Assumptions!$B$9*MAX(0,M10-Assumptions!$B$8)),0) -> 34103.084 | Y10: =X10-W10 -> 549.90396 | Z10: =(Z9-G9)*(1+Assumptions!$B$7) -> 124244.39 | AA10: =(AA9-L9)*(1+Assumptions!$B$7) -> 358812.63
A11: 2036 | B11: =A11-Assumptions!$B$29 -> 71 | C11: =A11-Assumptions!$B$30 -> 68 | D11: =IF(A11>=Assumptions!$B$23,Assumptions!$B$13*(1+Assumptions!$B$6)^(A11-Assumptions!$B$23),0) -> 63738.206 | E11: =IF(A11>=Assumptions!$B$24,Assumptions!$B$15,0) -> 25690 | F11: =IF(A11>=Assumptions!$B$23,Assumptions!$B$17,0) -> 8917 | G11: =MIN(Z11,MAX(IF(AND(A11>=2030,A11<=2034),Assumptions!$B$32,0),IF(B11<71,0,VLOOKUP(MIN(B11,95),Assumptions!$E$37:$F$61,2,TRUE()))*Z11)) -> 6756.9069 | H11: =D11+E11+F11+G11 -> 105102.11 | I11: =IF(A11>=Assumptions!$B$26,Assumptions!$B$14*(1+Assumptions!$B$6)^(A11-Assumptions!$B$26),0) -> 44701.477 | J11: =IF(A11>=Assumptions!$B$27,Assumptions!$B$16,0) -> 17185 | K11: =IF(A11>=Assumptions!$B$27,Assumptions!$B$18,0) -> 8917 | L11: =MIN(AA11,IF(C11<71,0,VLOOKUP(MIN(C11,95),Assumptions!$E$37:$F$61,2,TRUE()))*AA11) -> 0 | M11: =I11+J11+K11+L11 -> 70803.477 | N11: =D11+G11 -> 70495.113 | O11: =MIN(0.5*N11,MAX(0,(H11-M11)/2)) -> 17149.318 | P11: =H11-O11 -> 87952.795 | Q11: =M11+O11 -> 87952.795 | R11: =SUMPRODUCT(Assumptions!$B$36:$B$42,(P11-Assumptions!$A$36:$A$42)*((P11-Assumptions!$A$36:$A$42)>0)) -> 17639.978 | S11: =SUMPRODUCT(Assumptions!$B$36:$B$42,(Q11-Assumptions!$A$36:$A$42)*((Q11-Assumptions!$A$36:$A$42)>0)) -> 17639.978 | T11: =IF(B11>=65,MIN(F11,Assumptions!$B$9*MAX(0,P11-Assumptions!$B$8)),0) -> 0 | U11: =IF(C11>=65,MIN(K11,Assumptions!$B$9*MAX(0,Q11-Assumptions!$B$8)),0) -> 0 | V11: =H11+M11-R11-S11-T11-U11 -> 140625.64 | W11: =R11+S11+T11+U11 -> 35279.955 | X11: =SUMPRODUCT(Assumptions!$B$36:$B$42,(H11-Assumptions!$A$36:$A$42)*((H11-Assumptions!$A$36:$A$42)>0))+SUMPRODUCT(Assumptions!$B$36:$B$42,(M11-Assumptions!$A$36:$A$42)*((M11-Assumptions!$A$36:$A$42)>0))+IF(B11>=65,MIN(F11,Assumptions!$B$9*MAX(0,H11-Assumptions!$B$8)),0)+IF(C11>=65,MIN(K11,Assumptions!$B$9*MAX(0,M11-Assumptions!$B$8)),0) -> 36746.822 | Y11: =X11-W11 -> 1466.867 | Z11: =(Z10-G10)*(1+Assumptions!$B$7) -> 127971.72 | AA11: =(AA10-L10)*(1+Assumptions!$B$7) -> 369577
A12: 2037 | B12: =A12-Assumptions!$B$29 -> 72 | C12: =A12-Assumptions!$B$30 -> 69 | D12: =IF(A12>=Assumptions!$B$23,Assumptions!$B$13*(1+Assumptions!$B$6)^(A12-Assumptions!$B$23),0) -> 63100.824 | E12: =IF(A12>=Assumptions!$B$24,Assumptions!$B$15,0) -> 25690 | F12: =IF(A12>=Assumptions!$B$23,Assumptions!$B$17,0) -> 8917 | G12: =MIN(Z12,MAX(IF(AND(A12>=2030,A12<=2034),Assumptions!$B$32,0),IF(B12<71,0,VLOOKUP(MIN(B12,95),Assumptions!$E$37:$F$61,2,TRUE()))*Z12)) -> 6741.968 | H12: =D12+E12+F12+G12 -> 104449.79 | I12: =IF(A12>=Assumptions!$B$26,Assumptions!$B$14*(1+Assumptions!$B$6)^(A12-Assumptions!$B$26),0) -> 44254.463 | J12: =IF(A12>=Assumptions!$B$27,Assumptions!$B$16,0) -> 17185 | K12: =IF(A12>=Assumptions!$B$27,Assumptions!$B$18,0) -> 8917 | L12: =MIN(AA12,IF(C12<71,0,VLOOKUP(MIN(C12,95),Assumptions!$E$37:$F$61,2,TRUE()))*AA12) -> 0 | M12: =I12+J12+K12+L12 -> 70356.463 | N12: =D12+G12 -> 69842.792 | O12: =MIN(0.5*N12,MAX(0,(H12-M12)/2)) -> 17046.665 | P12: =H12-O12 -> 87403.127 | Q12: =M12+O12 -> 87403.127 | R12: =SUMPRODUCT(Assumptions!$B$36:$B$42,(P12-Assumptions!$A$36:$A$42)*((P12-Assumptions!$A$36:$A$42)>0)) -> 17472.329 | S12: =SUMPRODUCT(Assumptions!$B$36:$B$42,(Q12-Assumptions!$A$36:$A$42)*((Q12-Assumptions!$A$36:$A$42)>0)) -> 17472.329 | T12: =IF(B12>=65,MIN(F12,Assumptions!$B$9*MAX(0,P12-Assumptions!$B$8)),0) -> 0 | U12: =IF(C12>=65,MIN(K12,Assumptions!$B$9*MAX(0,Q12-Assumptions!$B$8)),0) -> 0 | V12: =H12+M12-R12-S12-T12-U12 -> 139861.6 | W12: =R12+S12+T12+U12 -> 34944.658 | X12: =SUMPRODUCT(Assumptions!$B$36:$B$42,(H12-Assumptions!$A$36:$A$42)*((H12-Assumptions!$A$36:$A$42)>0))+SUMPRODUCT(Assumptions!$B$36:$B$42,(M12-Assumptions!$A$36:$A$42)*((M12-Assumptions!$A$36:$A$42)>0))+IF(B12>=65,MIN(F12,Assumptions!$B$9*MAX(0,H12-Assumptions!$B$8)),0)+IF(C12>=65,MIN(K12,Assumptions!$B$9*MAX(0,M12-Assumptions!$B$8)),0) -> 36313.677 | Y12: =X12-W12 -> 1369.0188 | Z12: =(Z11-G11)*(1+Assumptions!$B$7) -> 124851.26 | AA12: =(AA11-L11)*(1+Assumptions!$B$7) -> 380664.31
A13: 2038 | B13: =A13-Assumptions!$B$29 -> 73 | C13: =A13-Assumptions!$B$30 -> 70 | D13: =IF(A13>=Assumptions!$B$23,Assumptions!$B$13*(1+Assumptions!$B$6)^(A13-Assumptions!$B$23),0) -> 62469.816 | E13: =IF(A13>=Assumptions!$B$24,Assumptions!$B$15,0) -> 25690 | F13: =IF(A13>=Assumptions!$B$23,Assumptions!$B$17,0) -> 8917 | G13: =MIN(Z13,MAX(IF(AND(A13>=2030,A13<=2034),Assumptions!$B$32,0),IF(B13<71,0,VLOOKUP(MIN(B13,95),Assumptions!$E$37:$F$61,2,TRUE()))*Z13)) -> 6727.3871 | H13: =D13+E13+F13+G13 -> 103804.2 | I13: =IF(A13>=Assumptions!$B$26,Assumptions!$B$14*(1+Assumptions!$B$6)^(A13-Assumptions!$B$26),0) -> 43811.918 | J13: =IF(A13>=Assumptions!$B$27,Assumptions!$B$16,0) -> 17185 | K13: =IF(A13>=Assumptions!$B$27,Assumptions!$B$18,0) -> 8917 | L13: =MIN(AA13,IF(C13<71,0,VLOOKUP(MIN(C13,95),Assumptions!$E$37:$F$61,2,TRUE()))*AA13) -> 0 | M13: =I13+J13+K13+L13 -> 69913.918 | N13: =D13+G13 -> 69197.203 | O13: =MIN(0.5*N13,MAX(0,(H13-M13)/2)) -> 16945.142 | P13: =H13-O13 -> 86859.061 | Q13: =M13+O13 -> 86859.061 | R13: =SUMPRODUCT(Assumptions!$B$36:$B$42,(P13-Assumptions!$A$36:$A$42)*((P13-Assumptions!$A$36:$A$42)>0)) -> 17306.388 | S13: =SUMPRODUCT(Assumptions!$B$36:$B$42,(Q13-Assumptions!$A$36:$A$42)*((Q13-Assumptions!$A$36:$A$42)>0)) -> 17306.388 | T13: =IF(B13>=65,MIN(F13,Assumptions!$B$9*MAX(0,P13-Assumptions!$B$8)),0) -> 0 | U13: =IF(C13>=65,MIN(K13,Assumptions!$B$9*MAX(0,Q13-Assumptions!$B$8)),0) -> 0 | V13: =H13+M13-R13-S13-T13-U13 -> 139105.34 | W13: =R13+S13+T13+U13 -> 34612.777 | X13: =SUMPRODUCT(Assumptions!$B$36:$B$42,(H13-Assumptions!$A$36:$A$42)*((H13-Assumptions!$A$36:$A$42)>0))+SUMPRODUCT(Assumptions!$B$36:$B$42,(M13-Assumptions!$A$36:$A$42)*((M13-Assumptions!$A$36:$A$42)>0))+IF(B13>=65,MIN(F13,Assumptions!$B$9*MAX(0,H13-Assumptions!$B$8)),0)+IF(C13>=65,MIN(K13,Assumptions!$B$9*MAX(0,M13-Assumptions!$B$8)),0) -> 35884.957 | Y13: =X13-W13 -> 1272.1804 | Z13: =(Z12-G12)*(1+Assumptions!$B$7) -> 121652.57 | AA13: =(AA12-L12)*(1+Assumptions!$B$7) -> 392084.24
A14: 2039 | B14: =A14-Assumptions!$B$29 -> 74 | C14: =A14-Assumptions!$B$30 -> 71 | D14: =IF(A14>=Assumptions!$B$23,Assumptions!$B$13*(1+Assumptions!$B$6)^(A14-Assumptions!$B$23),0) -> 61845.118 | E14: =IF(A14>=Assumptions!$B$24,Assumptions!$B$15,0) -> 25690 | F14: =IF(A14>=Assumptions!$B$23,Assumptions!$B$17,0) -> 8917 | G14: =MIN(Z14,MAX(IF(AND(A14>=2030,A14<=2034),Assumptions!$B$32,0),IF(B14<71,0,VLOOKUP(MIN(B14,95),Assumptions!$E$37:$F$61,2,TRUE()))*Z14)) -> 6711.7456 | H14: =D14+E14+F14+G14 -> 103163.86 | I14: =IF(A14>=Assumptions!$B$26,Assumptions!$B$14*(1+Assumptions!$B$6)^(A14-Assumptions!$B$26),0) -> 43373.799 | J14: =IF(A14>=Assumptions!$B$27,Assumptions!$B$16,0) -> 17185 | K14: =IF(A14>=Assumptions!$B$27,Assumptions!$B$18,0) -> 8917 | L14: =MIN(AA14,IF(C14<71,0,VLOOKUP(MIN(C14,95),Assumptions!$E$37:$F$61,2,TRUE()))*AA14) -> 21323.11 | M14: =I14+J14+K14+L14 -> 90798.908 | N14: =D14+G14 -> 68556.863 | O14: =MIN(0.5*N14,MAX(0,(H14-M14)/2)) -> 6182.4774 | P14: =H14-O14 -> 96981.386 | Q14: =M14+O14 -> 96981.386 | R14: =SUMPRODUCT(Assumptions!$B$36:$B$42,(P14-Assumptions!$A$36:$A$42)*((P14-Assumptions!$A$36:$A$42)>0)) -> 20393.698 | S14: =SUMPRODUCT(Assumptions!$B$36:$B$42,(Q14-Assumptions!$A$36:$A$42)*((Q14-Assumptions!$A$36:$A$42)>0)) -> 20393.698 | T14: =IF(B14>=65,MIN(F14,Assumptions!$B$9*MAX(0,P14-Assumptions!$B$8)),0) -> 248.75788 | U14: =IF(C14>=65,MIN(K14,Assumptions!$B$9*MAX(0,Q14-Assumptions!$B$8)),0) -> 248.75788 | V14: =H14+M14-R14-S14-T14-U14 -> 152677.86 | W14: =R14+S14+T14+U14 -> 41284.911 | X14: =SUMPRODUCT(Assumptions!$B$36:$B$42,(H14-Assumptions!$A$36:$A$42)*((H14-Assumptions!$A$36:$A$42)>0))+SUMPRODUCT(Assumptions!$B$36:$B$42,(M14-Assumptions!$A$36:$A$42)*((M14-Assumptions!$A$36:$A$42)>0))+IF(B14>=65,MIN(F14,Assumptions!$B$9*MAX(0,H14-Assumptions!$B$8)),0)+IF(C14>=65,MIN(K14,Assumptions!$B$9*MAX(0,M14-Assumptions!$B$8)),0) -> 41963.525 | Y14: =X14-W14 -> 678.61374 | Z14: =(Z13-G13)*(1+Assumptions!$B$7) -> 118372.94 | AA14: =(AA13-L13)*(1+Assumptions!$B$7) -> 403846.77
A15: 2040 | B15: =A15-Assumptions!$B$29 -> 75 | C15: =A15-Assumptions!$B$30 -> 72 | D15: =IF(A15>=Assumptions!$B$23,Assumptions!$B$13*(1+Assumptions!$B$6)^(A15-Assumptions!$B$23),0) -> 61226.666 | E15: =IF(A15>=Assumptions!$B$24,Assumptions!$B$15,0) -> 25690 | F15: =IF(A15>=Assumptions!$B$23,Assumptions!$B$17,0) -> 8917 | G15: =MIN(Z15,MAX(IF(AND(A15>=2030,A15<=2034),Assumptions!$B$32,0),IF(B15<71,0,VLOOKUP(MIN(B15,95),Assumptions!$E$37:$F$61,2,TRUE()))*Z15)) -> 6693.6418 | H15: =D15+E15+F15+G15 -> 102527.31 | I15: =IF(A15>=Assumptions!$B$26,Assumptions!$B$14*(1+Assumptions!$B$6)^(A15-Assumptions!$B$26),0) -> 42940.061 | J15: =IF(A15>=Assumptions!$B$27,Assumptions!$B$16,0) -> 17185 | K15: =IF(A15>=Assumptions!$B$27,Assumptions!$B$18,0) -> 8917 | L15: =MIN(AA15,IF(C15<71,0,VLOOKUP(MIN(C15,95),Assumptions!$E$37:$F$61,2,TRUE()))*AA15) -> 21275.966 | M15: =I15+J15+K15+L15 -> 90318.027 | N15: =D15+G15 -> 67920.308 | O15: =MIN(0.5*N15,MAX(0,(H15-M15)/2)) -> 6104.6407 | P15: =H15-O15 -> 96422.668 | Q15: =M15+O15 -> 96422.668 | R15: =SUMPRODUCT(Assumptions!$B$36:$B$42,(P15-Assumptions!$A$36:$A$42)*((P15-Assumptions!$A$36:$A$42)>0)) -> 20223.289 | S15: =SUMPRODUCT(Assumptions!$B$36:$B$42,(Q15-Assumptions!$A$36:$A$42)*((Q15-Assumptions!$A$36:$A$42)>0)) -> 20223.289 | T15: =IF(B15>=65,MIN(F15,Assumptions!$B$9*MAX(0,P15-Assumptions!$B$8)),0) -> 164.95015 | U15: =IF(C15>=65,MIN(K15,Assumptions!$B$9*MAX(0,Q15-Assumptions!$B$8)),0) -> 164.95015 | V15: =H15+M15-R15-S15-T15-U15 -> 152068.86 | W15: =R15+S15+T15+U15 -> 40776.478 | X15: =SUMPRODUCT(Assumptions!$B$36:$B$42,(H15-Assumptions!$A$36:$A$42)*((H15-Assumptions!$A$36:$A$42)>0))+SUMPRODUCT(Assumptions!$B$36:$B$42,(M15-Assumptions!$A$36:$A$42)*((M15-Assumptions!$A$36:$A$42)>0))+IF(B15>=65,MIN(F15,Assumptions!$B$9*MAX(0,H15-Assumptions!$B$8)),0)+IF(C15>=65,MIN(K15,Assumptions!$B$9*MAX(0,M15-Assumptions!$B$8)),0) -> 41527.224 | Y15: =X15-W15 -> 750.74595 | Z15: =(Z14-G14)*(1+Assumptions!$B$7) -> 115011.03 | AA15: =(AA14-L14)*(1+Assumptions!$B$7) -> 393999.37
A16: 2041 | B16: =A16-Assumptions!$B$29 -> 76 | C16: =A16-Assumptions!$B$30 -> 73 | D16: =IF(A16>=Assumptions!$B$23,Assumptions!$B$13*(1+Assumptions!$B$6)^(A16-Assumptions!$B$23),0) -> 60614.4 | E16: =IF(A16>=Assumptions!$B$24,Assumptions!$B$15,0) -> 25690 | F16: =IF(A16>=Assumptions!$B$23,Assumptions!$B$17,0) -> 8917 | G16: =MIN(Z16,MAX(IF(AND(A16>=2030,A16<=2034),Assumptions!$B$32,0),IF(B16<71,0,VLOOKUP(MIN(B16,95),Assumptions!$E$37:$F$61,2,TRUE()))*Z16)) -> 6671.7011 | H16: =D16+E16+F16+G16 -> 101893.1 | I16: =IF(A16>=Assumptions!$B$26,Assumptions!$B$14*(1+Assumptions!$B$6)^(A16-Assumptions!$B$26),0) -> 42510.66 | J16: =IF(A16>=Assumptions!$B$27,Assumptions!$B$16,0) -> 17185 | K16: =IF(A16>=Assumptions!$B$27,Assumptions!$B$18,0) -> 8917 | L16: =MIN(AA16,IF(C16<71,0,VLOOKUP(MIN(C16,95),Assumptions!$E$37:$F$61,2,TRUE()))*AA16) -> 21229.952 | M16: =I16+J16+K16+L16 -> 89842.613 | N16: =D16+G16 -> 67286.101 | O16: =MIN(0.5*N16,MAX(0,(H16-M16)/2)) -> 6025.2441 | P16: =H16-O16 -> 95867.857 | Q16: =M16+O16 -> 95867.857 | R16: =SUMPRODUCT(Assumptions!$B$36:$B$42,(P16-Assumptions!$A$36:$A$42)*((P16-Assumptions!$A$36:$A$42)>0)) -> 20054.071 | S16: =SUMPRODUCT(Assumptions!$B$36:$B$42,(Q16-Assumptions!$A$36:$A$42)*((Q16-Assumptions!$A$36:$A$42)>0)) -> 20054.071 | T16: =IF(B16>=65,MIN(F16,Assumptions!$B$9*MAX(0,P16-Assumptions!$B$8)),0) -> 81.728525 | U16: =IF(C16>=65,MIN(K16,Assumptions!$B$9*MAX(0,Q16-Assumptions!$B$8)),0) -> 81.728525 | V16: =H16+M16-R16-S16-T16-U16 -> 151464.11 | W16: =R16+S16+T16+U16 -> 40271.6 | X16: =SUMPRODUCT(Assumptions!$B$36:$B$42,(H16-Assumptions!$A$36:$A$42)*((H16-Assumptions!$A$36:$A$42)>0))+SUMPRODUCT(Assumptions!$B$36:$B$42,(M16-Assumptions!$A$36:$A$42)*((M16-Assumptions!$A$36:$A$42)>0))+IF(B16>=65,MIN(F16,Assumptions!$B$9*MAX(0,H16-Assumptions!$B$8)),0)+IF(C16>=65,MIN(K16,Assumptions!$B$9*MAX(0,M16-Assumptions!$B$8)),0) -> 41093.658 | Y16: =X16-W16 -> 822.05809 | Z16: =(Z15-G15)*(1+Assumptions!$B$7) -> 111566.91 | AA16: =(AA15-L15)*(1+Assumptions!$B$7) -> 383905.11
A17: 2042 | B17: =A17-Assumptions!$B$29 -> 77 | C17: =A17-Assumptions!$B$30 -> 74 | D17: =IF(A17>=Assumptions!$B$23,Assumptions!$B$13*(1+Assumptions!$B$6)^(A17-Assumptions!$B$23),0) -> 60008.256 | E17: =IF(A17>=Assumptions!$B$24,Assumptions!$B$15,0) -> 25690 | F17: =IF(A17>=Assumptions!$B$23,Assumptions!$B$17,0) -> 8917 | G17: =MIN(Z17,MAX(IF(AND(A17>=2030,A17<=2034),Assumptions!$B$32,0),IF(B17<71,0,VLOOKUP(MIN(B17,95),Assumptions!$E$37:$F$61,2,TRUE()))*Z17)) -> 6666.1953 | H17: =D17+E17+F17+G17 -> 101281.45 | I17: =IF(A17>=Assumptions!$B$26,Assumptions!$B$14*(1+Assumptions!$B$6)^(A17-Assumptions!$B$26),0) -> 42085.554 | J17: =IF(A17>=Assumptions!$B$27,Assumptions!$B$16,0) -> 17185 | K17: =IF(A17>=Assumptions!$B$27,Assumptions!$B$18,0) -> 8917 | L17: =MIN(AA17,IF(C17<71,0,VLOOKUP(MIN(C17,95),Assumptions!$E$37:$F$61,2,TRUE()))*AA17) -> 21180.592 | M17: =I17+J17+K17+L17 -> 89368.145 | N17: =D17+G17 -> 66674.451 | O17: =MIN(0.5*N17,MAX(0,(H17-M17)/2)) -> 5956.6528 | P17: =H17-O17 -> 95324.798 | Q17: =M17+O17 -> 95324.798 | R17: =SUMPRODUCT(Assumptions!$B$36:$B$42,(P17-Assumptions!$A$36:$A$42)*((P17-Assumptions!$A$36:$A$42)>0)) -> 19888.438 | S17: =SUMPRODUCT(Assumptions!$B$36:$B$42,(Q17-Assumptions!$A$36:$A$42)*((Q17-Assumptions!$A$36:$A$42)>0)) -> 19888.438 | T17: =IF(B17>=65,MIN(F17,Assumptions!$B$9*MAX(0,P17-Assumptions!$B$8)),0) -> 0.26974147 | U17: =IF(C17>=65,MIN(K17,Assumptions!$B$9*MAX(0,Q17-Assumptions!$B$8)),0) -> 0.26974147 | V17: =H17+M17-R17-S17-T17-U17 -> 150872.18 | W17: =R17+S17+T17+U17 -> 39777.416 | X17: =SUMPRODUCT(Assumptions!$B$36:$B$42,(H17-Assumptions!$A$36:$A$42)*((H17-Assumptions!$A$36:$A$42)>0))+SUMPRODUCT(Assumptions!$B$36:$B$42,(M17-Assumptions!$A$36:$A$42)*((M17-Assumptions!$A$36:$A$42)>0))+IF(B17>=65,MIN(F17,Assumptions!$B$9*MAX(0,H17-Assumptions!$B$8)),0)+IF(C17>=65,MIN(K17,Assumptions!$B$9*MAX(0,M17-Assumptions!$B$8)),0) -> 40670.645 | Y17: =X17-W17 -> 893.22818 | Z17: =(Z16-G16)*(1+Assumptions!$B$7) -> 108042.06 | AA17: =(AA16-L16)*(1+Assumptions!$B$7) -> 373555.41
... A30: 2055 | B30: =A30-Assumptions!$B$29 -> 90 | C30: =A30-Assumptions!$B$30 -> 87 | D30: =IF(A30>=Assumptions!$B$23,Assumptions!$B$13*(1+Assumptions!$B$6)^(A30-Assumptions!$B$23),0) -> 52658.506 | E30: =IF(A30>=Assumptions!$B$24,Assumptions!$B$15,0) -> 25690 | F30: =IF(A30>=Assumptions!$B$23,Assumptions!$B$17,0) -> 8917 | G30: =MIN(Z30,MAX(IF(AND(A30>=2030,A30<=2034),Assumptions!$B$32,0),IF(B30<71,0,VLOOKUP(MIN(B30,95),Assumptions!$E$37:$F$61,2,TRUE()))*Z30)) -> 6356.7548 | H30: =D30+E30+F30+G30 -> 93622.261 | I30: =IF(A30>=Assumptions!$B$26,Assumptions!$B$14*(1+Assumptions!$B$6)^(A30-Assumptions!$B$26),0) -> 36930.958 | J30: =IF(A30>=Assumptions!$B$27,Assumptions!$B$16,0) -> 17185 | K30: =IF(A30>=Assumptions!$B$27,Assumptions!$B$18,0) -> 8917 | L30: =MIN(AA30,IF(C30<71,0,VLOOKUP(MIN(C30,95),Assumptions!$E$37:$F$61,2,TRUE()))*AA30) -> 20345.959 | M30: =I30+J30+K30+L30 -> 83378.917 | N30: =D30+G30 -> 59015.261 | O30: =MIN(0.5*N30,MAX(0,(H30-M30)/2)) -> 5121.6719 | P30: =H30-O30 -> 88500.589 | Q30: =M30+O30 -> 88500.589 | R30: =SUMPRODUCT(Assumptions!$B$36:$B$42,(P30-Assumptions!$A$36:$A$42)*((P30-Assumptions!$A$36:$A$42)>0)) -> 17807.055 | S30: =SUMPRODUCT(Assumptions!$B$36:$B$42,(Q30-Assumptions!$A$36:$A$42)*((Q30-Assumptions!$A$36:$A$42)>0)) -> 17807.055 | T30: =IF(B30>=65,MIN(F30,Assumptions!$B$9*MAX(0,P30-Assumptions!$B$8)),0) -> 0 | U30: =IF(C30>=65,MIN(K30,Assumptions!$B$9*MAX(0,Q30-Assumptions!$B$8)),0) -> 0 | V30: =H30+M30-R30-S30-T30-U30 -> 141387.07 | W30: =R30+S30+T30+U30 -> 35614.109 | X30: =SUMPRODUCT(Assumptions!$B$36:$B$42,(H30-Assumptions!$A$36:$A$42)*((H30-Assumptions!$A$36:$A$42)>0))+SUMPRODUCT(Assumptions!$B$36:$B$42,(M30-Assumptions!$A$36:$A$42)*((M30-Assumptions!$A$36:$A$42)>0))+IF(B30>=65,MIN(F30,Assumptions!$B$9*MAX(0,H30-Assumptions!$B$8)),0)+IF(C30>=65,MIN(K30,Assumptions!$B$9*MAX(0,M30-Assumptions!$B$8)),0) -> 35614.109 | Y30: =X30-W30 -> 0 | Z30: =(Z29-G29)*(1+Assumptions!$B$7) -> 53328.48 | AA30: =(AA29-L29)*(1+Assumptions!$B$7) -> 213046.69
A31: TOTAL | V31: =SUM(V5:V30) -> 3695896.2 | W31: =SUM(W5:W30) -> 936096.77 | X31: =SUM(X5:X30) -> 954066.94 | Y31: =SUM(Y5:Y30) -> 17970.174

Sheet Assumptions
A1: Retirement Cash Flow Model — Assumptions
A2: Scenario: Retire Feb 2030 · Alec defers CPP to 70 · Andrea CPP & OAS at 65
A3: All figures in REAL 2026 dollars (inflation netted out). Blue = input you can change.
A4: Key assumptions
A5: CPI inflation (for reference) | B5: 0.025
A6: LAPP pension real growth (1.5% index − 2.5% CPI) | B6: -0.01
A7: Investment return, real | B7: 0.03
A8: OAS clawback threshold (CPI-indexed → constant real) | B8: 95323
A9: OAS clawback rate | B9: 0.15
A10: Tax-free band (combined basic personal amount, approx.) | B10: 21000
A12: Income building blocks (real 2026 $, annual)
A13: Alec LAPP starting pension (Feb 2030) | B13: 67700 | C13: Source: file 02 Income Sources
A14: Andrea LAPP starting pension (Feb 2030, validated) | B14: 47480 | C14: Source: file 02 Income Sources
A15: Alec CPP at 70 (deferred) | B15: 25690 | C15: Source: file 02 MSCA
A16: Andrea CPP at 65 | B16: 17185 | C16: Source: file 02 MSCA est ~95% max
A17: Alec OAS at 65 | B17: 8917 | C17: Source: file 02
A18: Andrea OAS at 65 | B18: 8917 | C18: Source: file 02
A19: Alec RRSP balance (2026) | B19: 200000 | C19: Source: file 03
A20: Andrea RRSP balance (2026) | B20: 275000 | C20: Source: file 03
A22: Start years
A23: Alec LAPP / OAS start | B23: 2030
A24: Alec CPP start (deferred to 70) | B24: 2035
A25: Alec RRIF conversion (year turns 71) | B25: 2036
A26: Andrea LAPP start | B26: 2030
A27: Andrea CPP / OAS start (age 65) | B27: 2033
A28: Andrea RRIF conversion (year turns 71) | B28: 2039
A29: Alec birth year | B29: 1965
A30: Andrea birth year | B30: 1968
A32: Alec discretionary RRIF meltdown, 2030–2034 (per yr, age 65–69) | B32: 25000
A33: (Assumes partial RRSP→RRIF at 65 so withdrawals are splittable)
A34: Alberta+Federal progressive tax (approx. 2026 — CONFIRM w/ accountant)
A35: Bracket floor | B35: Marginal Δ rate | C35: Cumulative rate | E35: RRIF minimum factors
A36: 21000 | B36: 0.23 | C36: 0.23 | E36: Age | F36: Min %
A37: 57375 | B37: 0.055 | C37: 0.285 | E37: 71 | F37: 0.0528
A38: 60000 | B38: 0.02 | C38: 0.305 | E38: 72 | F38: 0.054
A39: 114750 | B39: 0.055 | C39: 0.36 | E39: 73 | F39: 0.0553
A40: 151234 | B40: 0.02 | C40: 0.38 | E40: 74 | F40: 0.0567
A41: 177882 | B41: 0.03 | C41: 0.41 | E41: 75 | F41: 0.0582
A42: 181481 | B42: 0.01 | C42: 0.42 | E42: 76 | F42: 0.0598
E43: 77 | F43: 0.0617
...
