Workbook

Sheet Loan Calculator
A1: CAR LOAN INPUTS | D1: RESULTS SUMMARY
A2: Current Loan Balance | B2: 36890 | D2: Starting Balance After Lump Sum #1 | E2: =B2-B10 -> 27390
A3: Annual Interest Rate | B3: 0.06 | D3: Total Periods to Payoff | E3: =Amortization!M2 -> 57
A4: Biweekly Payment | B4: 365.72 | D4: Years to Payoff | E4: =E3/B5 -> 2.1923077
A5: Payments Per Year | B5: 26 | D5: Total Interest Paid | E5: =Amortization!M3 -> 1973.6559
A6: Start Date (for reference) | B6: Apr 2026 | D6: Total Payments Made | E6: =Amortization!M4 -> 29363.656
A7: Rate Per Period | B7: =B3/B5 -> 0.0023076923 | D7: Total Lump Sums Applied | E7: =B10+B11+B13 -> 9500
A9: LUMP SUM PAYMENTS | D9: BASELINE COMPARISON
A10: Lump Sum #1 (apply at start) | B10: 9500 | D10: Baseline Periods (no changes) | E10: =Baseline!J2 -> 115
A11: Lump Sum #2 Amount | B11: 0 | D11: Baseline Total Interest | E11: =Baseline!J3 -> 5151.5318
A12: Lump Sum #2 - Apply at Period # | B12: 0 | D12: Periods Saved | E12: =E10-E3 -> 58
A13: Lump Sum #3 Amount | B13: 0 | D13: Interest Saved | E13: =E11-E5 -> 3177.8759
A14: Lump Sum #3 - Apply at Period # | B14: 0 | D14: Years Saved | E14: =E12/B5 -> 2.2307692
A16: PAYMENT INCREASES
A17: Extra Payment #1 Amount (biweekly) | B17: 197.44
A18: Extra Payment #1 - Starts at Period # | B18: 13
A19: Extra Payment #2 Amount (biweekly) | B19: 0
A20: Extra Payment #2 - Starts at Period # | B20: 0
A21: Extra Payment #3 Amount (biweekly) | B21: 0
A22: Extra Payment #3 - Starts at Period # | B22: 0
A24: HOW TO USE
A25: Change any BLUE value above to model different scenarios.
A26: Lump Sum #1 is applied immediately. #2 and #3 apply at the period you specify.
A27: Extra Payments add to your biweekly payment starting at the period you specify.
A28: Example: Wife's car paid off at period 13 → enter 197.44 as Extra Payment #1 starting at period 13.
A29: The Amortization tab shows the full period-by-period breakdown.
A30: The Baseline tab shows what happens with no changes for comparison.

Sheet Amortization
A1: Period | B1: Opening Balance | C1: Lump Sum Applied | D1: Payment | E1: Extra Payment | F1: Total Payment | G1: Interest | H1: Principal | I1: Closing Balance | J1: Cumulative Interest | L1: Summary
A2: 1 | B2: ='Loan Calculator'!B2-'Loan Calculator'!B10 -> 27390 | C2: =IF(B2<=0,0,IF(A2='Loan Calculator'!B12,MIN('Loan Calculator'!B11,B2),0)+IF(A2='Loan Calculator'!B14,MIN('Loan Calculator'!B13,B2),0)) -> 0 | D2: =IF(B2<=0,0,'Loan Calculator'!B4) -> 365.72 | E2: =IF(B2<=0,0,IF(A2>='Loan Calculator'!B18,'Loan Calculator'!B17,0)+IF(A2>='Loan Calculator'!B20,'Loan Calculator'!B19,0)+IF(A2>='Loan Calculator'!B22,'Loan Calculator'!B21,0)) -> 0 | F2: =IF(B2<=0,0,MIN(D2+E2,(B2-C2)*(1+'Loan Calculator'!B7))) -> 365.72 | G2: =IF(B2<=0,0,MAX(0,(B2-C2)*'Loan Calculator'!B7)) -> 63.207692 | H2: =IF(B2<=0,0,F2-G2) -> 302.51231 | I2: =IF(B2<=0,0,MAX(0,B2-C2-H2)) -> 27087.488 | J2: =G2 -> 63.207692 | L2: Total Periods: | M2: =COUNTIF(B2:B201,">"&0) -> 57
A3: 2 | B3: =MAX(0,I2) -> 27087.488 | C3: =IF(B3<=0,0,IF(A3='Loan Calculator'!B12,MIN('Loan Calculator'!B11,B3),0)+IF(A3='Loan Calculator'!B14,MIN('Loan Calculator'!B13,B3),0)) -> 0 | D3: =IF(B3<=0,0,'Loan Calculator'!B4) -> 365.72 | E3: =IF(B3<=0,0,IF(A3>='Loan Calculator'!B18,'Loan Calculator'!B17,0)+IF(A3>='Loan Calculator'!B20,'Loan Calculator'!B19,0)+IF(A3>='Loan Calculator'!B22,'Loan Calculator'!B21,0)) -> 0 | F3: =IF(B3<=0,0,MIN(D3+E3,(B3-C3)*(1+'Loan Calculator'!B7))) -> 365.72 | G3: =IF(B3<=0,0,MAX(0,(B3-C3)*'Loan Calculator'!B7)) -> 62.509587 | H3: =IF(B3<=0,0,F3-G3) -> 303.21041 | I3: =IF(B3<=0,0,MAX(0,B3-C3-H3)) -> 26784.277 | J3: =J2+G3 -> 125.71728 | L3: Total Interest: | M3: =SUM(G2:G201) -> 1973.6559
A4: 3 | B4: =MAX(0,I3) -> 26784.277 | C4: =IF(B4<=0,0,IF(A4='Loan Calculator'!B12,MIN('Loan Calculator'!B11,B4),0)+IF(A4='Loan Calculator'!B14,MIN('Loan Calculator'!B13,B4),0)) -> 0 | D4: =IF(B4<=0,0,'Loan Calculator'!B4) -> 365.72 | E4: =IF(B4<=0,0,IF(A4>='Loan Calculator'!B18,'Loan Calculator'!B17,0)+IF(A4>='Loan Calculator'!B20,'Loan Calculator'!B19,0)+IF(A4>='Loan Calculator'!B22,'Loan Calculator'!B21,0)) -> 0 | F4: =IF(B4<=0,0,MIN(D4+E4,(B4-C4)*(1+'Loan Calculator'!B7))) -> 365.72 | G4: =IF(B4<=0,0,MAX(0,(B4-C4)*'Loan Calculator'!B7)) -> 61.809871 | H4: =IF(B4<=0,0,F4-G4) -> 303.91013 | I4: =IF(B4<=0,0,MAX(0,B4-C4-H4)) -> 26480.367 | J4: =J3+G4 -> 187.52715 | L4: Total Payments: | M4: =SUM(F2:F201)+SUM(C2:C201) -> 29363.656
A5: 4 | B5: =MAX(0,I4) -> 26480.367 | C5: =IF(B5<=0,0,IF(A5='Loan Calculator'!B12,MIN('Loan Calculator'!B11,B5),0)+IF(A5='Loan Calculator'!B14,MIN('Loan Calculator'!B13,B5),0)) -> 0 | D5: =IF(B5<=0,0,'Loan Calculator'!B4) -> 365.72 | E5: =IF(B5<=0,0,IF(A5>='Loan Calculator'!B18,'Loan Calculator'!B17,0)+IF(A5>='Loan Calculator'!B20,'Loan Calculator'!B19,0)+IF(A5>='Loan Calculator'!B22,'Loan Calculator'!B21,0)) -> 0 | F5: =IF(B5<=0,0,MIN(D5+E5,(B5-C5)*(1+'Loan Calculator'!B7))) -> 365.72 | G5: =IF(B5<=0,0,MAX(0,(B5-C5)*'Loan Calculator'!B7)) -> 61.10854 | H5: =IF(B5<=0,0,F5-G5) -> 304.61146 | I5: =IF(B5<=0,0,MAX(0,B5-C5-H5)) -> 26175.756 | J5: =J4+G5 -> 248.63569
A6: 5 | B6: =MAX(0,I5) -> 26175.756 | C6: =IF(B6<=0,0,IF(A6='Loan Calculator'!B12,MIN('Loan Calculator'!B11,B6),0)+IF(A6='Loan Calculator'!B14,MIN('Loan Calculator'!B13,B6),0)) -> 0 | D6: =IF(B6<=0,0,'Loan Calculator'!B4) -> 365.72 | E6: =IF(B6<=0,0,IF(A6>='Loan Calculator'!B18,'Loan Calculator'!B17,0)+IF(A6>='Loan Calculator'!B20,'Loan Calculator'!B19,0)+IF(A6>='Loan Calculator'!B22,'Loan Calculator'!B21,0)) -> 0 | F6: =IF(B6<=0,0,MIN(D6+E6,(B6-C6)*(1+'Loan Calculator'!B7))) -> 365.72 | G6: =IF(B6<=0,0,MAX(0,(B6-C6)*'Loan Calculator'!B7)) -> 60.40559 | H6: =IF(B6<=0,0,F6-G6) -> 305.31441 | I6: =IF(B6<=0,0,MAX(0,B6-C6-H6)) -> 25870.441 | J6: =J5+G6 -> 309.04128
A7: 6 | B7: =MAX(0,I6) -> 25870.441 | C7: =IF(B7<=0,0,IF(A7='Loan Calculator'!B12,MIN('Loan Calculator'!B11,B7),0)+IF(A7='Loan Calculator'!B14,MIN('Loan Calculator'!B13,B7),0)) -> 0 | D7: =IF(B7<=0,0,'Loan Calculator'!B4) -> 365.72 | E7: =IF(B7<=0,0,IF(A7>='Loan Calculator'!B18,'Loan Calculator'!B17,0)+IF(A7>='Loan Calculator'!B20,'Loan Calculator'!B19,0)+IF(A7>='Loan Calculator'!B22,'Loan Calculator'!B21,0)) -> 0 | F7: =IF(B7<=0,0,MIN(D7+E7,(B7-C7)*(1+'Loan Calculator'!B7))) -> 365.72 | G7: =IF(B7<=0,0,MAX(0,(B7-C7)*'Loan Calculator'!B7)) -> 59.701018 | H7: =IF(B7<=0,0,F7-G7) -> 306.01898 | I7: =IF(B7<=0,0,MAX(0,B7-C7-H7)) -> 25564.422 | J7: =J6+G7 -> 368.7423
A8: 7 | B8: =MAX(0,I7) -> 25564.422 | C8: =IF(B8<=0,0,IF(A8='Loan Calculator'!B12,MIN('Loan Calculator'!B11,B8),0)+IF(A8='Loan Calculator'!B14,MIN('Loan Calculator'!B13,B8),0)) -> 0 | D8: =IF(B8<=0,0,'Loan Calculator'!B4) -> 365.72 | E8: =IF(B8<=0,0,IF(A8>='Loan Calculator'!B18,'Loan Calculator'!B17,0)+IF(A8>='Loan Calculator'!B20,'Loan Calculator'!B19,0)+IF(A8>='Loan Calculator'!B22,'Loan Calculator'!B21,0)) -> 0 | F8: =IF(B8<=0,0,MIN(D8+E8,(B8-C8)*(1+'Loan Calculator'!B7))) -> 365.72 | G8: =IF(B8<=0,0,MAX(0,(B8-C8)*'Loan Calculator'!B7)) -> 58.994821 | H8: =IF(B8<=0,0,F8-G8) -> 306.72518 | I8: =IF(B8<=0,0,MAX(0,B8-C8-H8)) -> 25257.697 | J8: =J7+G8 -> 427.73712
A9: 8 | B9: =MAX(0,I8) -> 25257.697 | C9: =IF(B9<=0,0,IF(A9='Loan Calculator'!B12,MIN('Loan Calculator'!B11,B9),0)+IF(A9='Loan Calculator'!B14,MIN('Loan Calculator'!B13,B9),0)) -> 0 | D9: =IF(B9<=0,0,'Loan Calculator'!B4) -> 365.72 | E9: =IF(B9<=0,0,IF(A9>='Loan Calculator'!B18,'Loan Calculator'!B17,0)+IF(A9>='Loan Calculator'!B20,'Loan Calculator'!B19,0)+IF(A9>='Loan Calculator'!B22,'Loan Calculator'!B21,0)) -> 0 | F9: =IF(B9<=0,0,MIN(D9+E9,(B9-C9)*(1+'Loan Calculator'!B7))) -> 365.72 | G9: =IF(B9<=0,0,MAX(0,(B9-C9)*'Loan Calculator'!B7)) -> 58.286993 | H9: =IF(B9<=0,0,F9-G9) -> 307.43301 | I9: =IF(B9<=0,0,MAX(0,B9-C9-H9)) -> 24950.264 | J9: =J8+G9 -> 486.02411
A10: 9 | B10: =MAX(0,I9) -> 24950.264 | C10: =IF(B10<=0,0,IF(A10='Loan Calculator'!B12,MIN('Loan Calculator'!B11,B10),0)+IF(A10='Loan Calculator'!B14,MIN('Loan Calculator'!B13,B10),0)) -> 0 | D10: =IF(B10<=0,0,'Loan Calculator'!B4) -> 365.72 | E10: =IF(B10<=0,0,IF(A10>='Loan Calculator'!B18,'Loan Calculator'!B17,0)+IF(A10>='Loan Calculator'!B20,'Loan Calculator'!B19,0)+IF(A10>='Loan Calculator'!B22,'Loan Calculator'!B21,0)) -> 0 | F10: =IF(B10<=0,0,MIN(D10+E10,(B10-C10)*(1+'Loan Calculator'!B7))) -> 365.72 | G10: =IF(B10<=0,0,MAX(0,(B10-C10)*'Loan Calculator'!B7)) -> 57.577533 | H10: =IF(B10<=0,0,F10-G10) -> 308.14247 | I10: =IF(B10<=0,0,MAX(0,B10-C10-H10)) -> 24642.122 | J10: =J9+G10 -> 543.60164
A11: 10 | B11: =MAX(0,I10) -> 24642.122 | C11: =IF(B11<=0,0,IF(A11='Loan Calculator'!B12,MIN('Loan Calculator'!B11,B11),0)+IF(A11='Loan Calculator'!B14,MIN('Loan Calculator'!B13,B11),0)) -> 0 | D11: =IF(B11<=0,0,'Loan Calculator'!B4) -> 365.72 | E11: =IF(B11<=0,0,IF(A11>='Loan Calculator'!B18,'Loan Calculator'!B17,0)+IF(A11>='Loan Calculator'!B20,'Loan Calculator'!B19,0)+IF(A11>='Loan Calculator'!B22,'Loan Calculator'!B21,0)) -> 0 | F11: =IF(B11<=0,0,MIN(D11+E11,(B11-C11)*(1+'Loan Calculator'!B7))) -> 365.72 | G11: =IF(B11<=0,0,MAX(0,(B11-C11)*'Loan Calculator'!B7)) -> 56.866435 | H11: =IF(B11<=0,0,F11-G11) -> 308.85357 | I11: =IF(B11<=0,0,MAX(0,B11-C11-H11)) -> 24333.268 | J11: =J10+G11 -> 600.46808
A12: 11 | B12: =MAX(0,I11) -> 24333.268 | C12: =IF(B12<=0,0,IF(A12='Loan Calculator'!B12,MIN('Loan Calculator'!B11,B12),0)+IF(A12='Loan Calculator'!B14,MIN('Loan Calculator'!B13,B12),0)) -> 0 | D12: =IF(B12<=0,0,'Loan Calculator'!B4) -> 365.72 | E12: =IF(B12<=0,0,IF(A12>='Loan Calculator'!B18,'Loan Calculator'!B17,0)+IF(A12>='Loan Calculator'!B20,'Loan Calculator'!B19,0)+IF(A12>='Loan Calculator'!B22,'Loan Calculator'!B21,0)) -> 0 | F12: =IF(B12<=0,0,MIN(D12+E12,(B12-C12)*(1+'Loan Calculator'!B7))) -> 365.72 | G12: =IF(B12<=0,0,MAX(0,(B12-C12)*'Loan Calculator'!B7)) -> 56.153696 | H12: =IF(B12<=0,0,F12-G12) -> 309.5663 | I12: =IF(B12<=0,0,MAX(0,B12-C12-H12)) -> 24023.702 | J12: =J11+G12 -> 656.62177
A13: 12 | B13: =MAX(0,I12) -> 24023.702 | C13: =IF(B13<=0,0,IF(A13='Loan Calculator'!B12,MIN('Loan Calculator'!B11,B13),0)+IF(A13='Loan Calculator'!B14,MIN('Loan Calculator'!B13,B13),0)) -> 0 | D13: =IF(B13<=0,0,'Loan Calculator'!B4) -> 365.72 | E13: =IF(B13<=0,0,IF(A13>='Loan Calculator'!B18,'Loan Calculator'!B17,0)+IF(A13>='Loan Calculator'!B20,'Loan Calculator'!B19,0)+IF(A13>='Loan Calculator'!B22,'Loan Calculator'!B21,0)) -> 0 | F13: =IF(B13<=0,0,MIN(D13+E13,(B13-C13)*(1+'Loan Calculator'!B7))) -> 365.72 | G13: =IF(B13<=0,0,MAX(0,(B13-C13)*'Loan Calculator'!B7)) -> 55.439312 | H13: =IF(B13<=0,0,F13-G13) -> 310.28069 | I13: =IF(B13<=0,0,MAX(0,B13-C13-H13)) -> 23713.421 | J13: =J12+G13 -> 712.06109
A14: 13 | B14: =MAX(0,I13) -> 23713.421 | C14: =IF(B14<=0,0,IF(A14='Loan Calculator'!B12,MIN('Loan Calculator'!B11,B14),0)+IF(A14='Loan Calculator'!B14,MIN('Loan Calculator'!B13,B14),0)) -> 0 | D14: =IF(B14<=0,0,'Loan Calculator'!B4) -> 365.72 | E14: =IF(B14<=0,0,IF(A14>='Loan Calculator'!B18,'Loan Calculator'!B17,0)+IF(A14>='Loan Calculator'!B20,'Loan Calculator'!B19,0)+IF(A14>='Loan Calculator'!B22,'Loan Calculator'!B21,0)) -> 197.44 | F14: =IF(B14<=0,0,MIN(D14+E14,(B14-C14)*(1+'Loan Calculator'!B7))) -> 563.16 | G14: =IF(B14<=0,0,MAX(0,(B14-C14)*'Loan Calculator'!B7)) -> 54.723279 | H14: =IF(B14<=0,0,F14-G14) -> 508.43672 | I14: =IF(B14<=0,0,MAX(0,B14-C14-H14)) -> 23204.984 | J14: =J13+G14 -> 766.78437
A15: 14 | B15: =MAX(0,I14) -> 23204.984 | C15: =IF(B15<=0,0,IF(A15='Loan Calculator'!B12,MIN('Loan Calculator'!B11,B15),0)+IF(A15='Loan Calculator'!B14,MIN('Loan Calculator'!B13,B15),0)) -> 0 | D15: =IF(B15<=0,0,'Loan Calculator'!B4) -> 365.72 | E15: =IF(B15<=0,0,IF(A15>='Loan Calculator'!B18,'Loan Calculator'!B17,0)+IF(A15>='Loan Calculator'!B20,'Loan Calculator'!B19,0)+IF(A15>='Loan Calculator'!B22,'Loan Calculator'!B21,0)) -> 197.44 | F15: =IF(B15<=0,0,MIN(D15+E15,(B15-C15)*(1+'Loan Calculator'!B7))) -> 563.16 | G15: =IF(B15<=0,0,MAX(0,(B15-C15)*'Loan Calculator'!B7)) -> 53.549964 | H15: =IF(B15<=0,0,F15-G15) -> 509.61004 | I15: =IF(B15<=0,0,MAX(0,B15-C15-H15)) -> 22695.374 | J15: =J14+G15 -> 820.33433
A16: 15 | B16: =MAX(0,I15) -> 22695.374 | C16: =IF(B16<=0,0,IF(A16='Loan Calculator'!B12,MIN('Loan Calculator'!B11,B16),0)+IF(A16='Loan Calculator'!B14,MIN('Loan Calculator'!B13,B16),0)) -> 0 | D16: =IF(B16<=0,0,'Loan Calculator'!B4) -> 365.72 | E16: =IF(B16<=0,0,IF(A16>='Loan Calculator'!B18,'Loan Calculator'!B17,0)+IF(A16>='Loan Calculator'!B20,'Loan Calculator'!B19,0)+IF(A16>='Loan Calculator'!B22,'Loan Calculator'!B21,0)) -> 197.44 | F16: =IF(B16<=0,0,MIN(D16+E16,(B16-C16)*(1+'Loan Calculator'!B7))) -> 563.16 | G16: =IF(B16<=0,0,MAX(0,(B16-C16)*'Loan Calculator'!B7)) -> 52.373941 | H16: =IF(B16<=0,0,F16-G16) -> 510.78606 | I16: =IF(B16<=0,0,MAX(0,B16-C16-H16)) -> 22184.588 | J16: =J15+G16 -> 872.70827
A17: 16 | B17: =MAX(0,I16) -> 22184.588 | C17: =IF(B17<=0,0,IF(A17='Loan Calculator'!B12,MIN('Loan Calculator'!B11,B17),0)+IF(A17='Loan Calculator'!B14,MIN('Loan Calculator'!B13,B17),0)) -> 0 | D17: =IF(B17<=0,0,'Loan Calculator'!B4) -> 365.72 | E17: =IF(B17<=0,0,IF(A17>='Loan Calculator'!B18,'Loan Calculator'!B17,0)+IF(A17>='Loan Calculator'!B20,'Loan Calculator'!B19,0)+IF(A17>='Loan Calculator'!B22,'Loan Calculator'!B21,0)) -> 197.44 | F17: =IF(B17<=0,0,MIN(D17+E17,(B17-C17)*(1+'Loan Calculator'!B7))) -> 563.16 | G17: =IF(B17<=0,0,MAX(0,(B17-C17)*'Loan Calculator'!B7)) -> 51.195204 | H17: =IF(B17<=0,0,F17-G17) -> 511.9648 | I17: =IF(B17<=0,0,MAX(0,B17-C17-H17)) -> 21672.623 | J17: =J16+G17 -> 923.90347
A18: 17 | B18: =MAX(0,I17) -> 21672.623 | C18: =IF(B18<=0,0,IF(A18='Loan Calculator'!B12,MIN('Loan Calculator'!B11,B18),0)+IF(A18='Loan Calculator'!B14,MIN('Loan Calculator'!B13,B18),0)) -> 0 | D18: =IF(B18<=0,0,'Loan Calculator'!B4) -> 365.72 | E18: =IF(B18<=0,0,IF(A18>='Loan Calculator'!B18,'Loan Calculator'!B17,0)+IF(A18>='Loan Calculator'!B20,'Loan Calculator'!B19,0)+IF(A18>='Loan Calculator'!B22,'Loan Calculator'!B21,0)) -> 197.44 | F18: =IF(B18<=0,0,MIN(D18+E18,(B18-C18)*(1+'Loan Calculator'!B7))) -> 563.16 | G18: =IF(B18<=0,0,MAX(0,(B18-C18)*'Loan Calculator'!B7)) -> 50.013746 | H18: =IF(B18<=0,0,F18-G18) -> 513.14625 | I18: =IF(B18<=0,0,MAX(0,B18-C18-H18)) -> 21159.477 | J18: =J17+G18 -> 973.91722
A19: 18 | B19: =MAX(0,I18) -> 21159.477 | C19: =IF(B19<=0,0,IF(A19='Loan Calculator'!B12,MIN('Loan Calculator'!B11,B19),0)+IF(A19='Loan Calculator'!B14,MIN('Loan Calculator'!B13,B19),0)) -> 0 | D19: =IF(B19<=0,0,'Loan Calculator'!B4) -> 365.72 | E19: =IF(B19<=0,0,IF(A19>='Loan Calculator'!B18,'Loan Calculator'!B17,0)+IF(A19>='Loan Calculator'!B20,'Loan Calculator'!B19,0)+IF(A19>='Loan Calculator'!B22,'Loan Calculator'!B21,0)) -> 197.44 | F19: =IF(B19<=0,0,MIN(D19+E19,(B19-C19)*(1+'Loan Calculator'!B7))) -> 563.16 | G19: =IF(B19<=0,0,MAX(0,(B19-C19)*'Loan Calculator'!B7)) -> 48.829563 | H19: =IF(B19<=0,0,F19-G19) -> 514.33044 | I19: =IF(B19<=0,0,MAX(0,B19-C19-H19)) -> 20645.147 | J19: =J18+G19 -> 1022.7468
A20: 19 | B20: =MAX(0,I19) -> 20645.147 | C20: =IF(B20<=0,0,IF(A20='Loan Calculator'!B12,MIN('Loan Calculator'!B11,B20),0)+IF(A20='Loan Calculator'!B14,MIN('Loan Calculator'!B13,B20),0)) -> 0 | D20: =IF(B20<=0,0,'Loan Calculator'!B4) -> 365.72 | E20: =IF(B20<=0,0,IF(A20>='Loan Calculator'!B18,'Loan Calculator'!B17,0)+IF(A20>='Loan Calculator'!B20,'Loan Calculator'!B19,0)+IF(A20>='Loan Calculator'!B22,'Loan Calculator'!B21,0)) -> 197.44 | F20: =IF(B20<=0,0,MIN(D20+E20,(B20-C20)*(1+'Loan Calculator'!B7))) -> 563.16 | G20: =IF(B20<=0,0,MAX(0,(B20-C20)*'Loan Calculator'!B7)) -> 47.642646 | H20: =IF(B20<=0,0,F20-G20) -> 515.51735 | I20: =IF(B20<=0,0,MAX(0,B20-C20-H20)) -> 20129.629 | J20: =J19+G20 -> 1070.3894
A21: 20 | B21: =MAX(0,I20) -> 20129.629 | C21: =IF(B21<=0,0,IF(A21='Loan Calculator'!B12,MIN('Loan Calculator'!B11,B21),0)+IF(A21='Loan Calculator'!B14,MIN('Loan Calculator'!B13,B21),0)) -> 0 | D21: =IF(B21<=0,0,'Loan Calculator'!B4) -> 365.72 | E21: =IF(B21<=0,0,IF(A21>='Loan Calculator'!B18,'Loan Calculator'!B17,0)+IF(A21>='Loan Calculator'!B20,'Loan Calculator'!B19,0)+IF(A21>='Loan Calculator'!B22,'Loan Calculator'!B21,0)) -> 197.44 | F21: =IF(B21<=0,0,MIN(D21+E21,(B21-C21)*(1+'Loan Calculator'!B7))) -> 563.16 | G21: =IF(B21<=0,0,MAX(0,(B21-C21)*'Loan Calculator'!B7)) -> 46.452991 | H21: =IF(B21<=0,0,F21-G21) -> 516.70701 | I21: =IF(B21<=0,0,MAX(0,B21-C21-H21)) -> 19612.922 | J21: =J20+G21 -> 1116.8424
A22: 21 | B22: =MAX(0,I21) -> 19612.922 | C22: =IF(B22<=0,0,IF(A22='Loan Calculator'!B12,MIN('Loan Calculator'!B11,B22),0)+IF(A22='Loan Calculator'!B14,MIN('Loan Calculator'!B13,B22),0)) -> 0 | D22: =IF(B22<=0,0,'Loan Calculator'!B4) -> 365.72 | E22: =IF(B22<=0,0,IF(A22>='Loan Calculator'!B18,'Loan Calculator'!B17,0)+IF(A22>='Loan Calculator'!B20,'Loan Calculator'!B19,0)+IF(A22>='Loan Calculator'!B22,'Loan Calculator'!B21,0)) -> 197.44 | F22: =IF(B22<=0,0,MIN(D22+E22,(B22-C22)*(1+'Loan Calculator'!B7))) -> 563.16 | G22: =IF(B22<=0,0,MAX(0,(B22-C22)*'Loan Calculator'!B7)) -> 45.26059 | H22: =IF(B22<=0,0,F22-G22) -> 517.89941 | I22: =IF(B22<=0,0,MAX(0,B22-C22-H22)) -> 19095.023 | J22: =J21+G22 -> 1162.103
A23: 22 | B23: =MAX(0,I22) -> 19095.023 | C23: =IF(B23<=0,0,IF(A23='Loan Calculator'!B12,MIN('Loan Calculator'!B11,B23),0)+IF(A23='Loan Calculator'!B14,MIN('Loan Calculator'!B13,B23),0)) -> 0 | D23: =IF(B23<=0,0,'Loan Calculator'!B4) -> 365.72 | E23: =IF(B23<=0,0,IF(A23>='Loan Calculator'!B18,'Loan Calculator'!B17,0)+IF(A23>='Loan Calculator'!B20,'Loan Calculator'!B19,0)+IF(A23>='Loan Calculator'!B22,'Loan Calculator'!B21,0)) -> 197.44 | F23: =IF(B23<=0,0,MIN(D23+E23,(B23-C23)*(1+'Loan Calculator'!B7))) -> 563.16 | G23: =IF(B23<=0,0,MAX(0,(B23-C23)*'Loan Calculator'!B7)) -> 44.065438 | H23: =IF(B23<=0,0,F23-G23) -> 519.09456 | I23: =IF(B23<=0,0,MAX(0,B23-C23-H23)) -> 18575.928 | J23: =J22+G23 -> 1206.1684
A24: 23 | B24: =MAX(0,I23) -> 18575.928 | C24: =IF(B24<=0,0,IF(A24='Loan Calculator'!B12,MIN('Loan Calculator'!B11,B24),0)+IF(A24='Loan Calculator'!B14,MIN('Loan Calculator'!B13,B24),0)) -> 0 | D24: =IF(B24<=0,0,'Loan Calculator'!B4) -> 365.72 | E24: =IF(B24<=0,0,IF(A24>='Loan Calculator'!B18,'Loan Calculator'!B17,0)+IF(A24>='Loan Calculator'!B20,'Loan Calculator'!B19,0)+IF(A24>='Loan Calculator'!B22,'Loan Calculator'!B21,0)) -> 197.44 | F24: =IF(B24<=0,0,MIN(D24+E24,(B24-C24)*(1+'Loan Calculator'!B7))) -> 563.16 | G24: =IF(B24<=0,0,MAX(0,(B24-C24)*'Loan Calculator'!B7)) -> 42.867527 | H24: =IF(B24<=0,0,F24-G24) -> 520.29247 | I24: =IF(B24<=0,0,MAX(0,B24-C24-H24)) -> 18055.636 | J24: =J23+G24 -> 1249.036
A25: 24 | B25: =MAX(0,I24) -> 18055.636 | C25: =IF(B25<=0,0,IF(A25='Loan Calculator'!B12,MIN('Loan Calculator'!B11,B25),0)+IF(A25='Loan Calculator'!B14,MIN('Loan Calculator'!B13,B25),0)) -> 0 | D25: =IF(B25<=0,0,'Loan Calculator'!B4) -> 365.72 | E25: =IF(B25<=0,0,IF(A25>='Loan Calculator'!B18,'Loan Calculator'!B17,0)+IF(A25>='Loan Calculator'!B20,'Loan Calculator'!B19,0)+IF(A25>='Loan Calculator'!B22,'Loan Calculator'!B21,0)) -> 197.44 | F25: =IF(B25<=0,0,MIN(D25+E25,(B25-C25)*(1+'Loan Calculator'!B7))) -> 563.16 | G25: =IF(B25<=0,0,MAX(0,(B25-C25)*'Loan Calculator'!B7)) -> 41.666852 | H25: =IF(B25<=0,0,F25-G25) -> 521.49315 | I25: =IF(B25<=0,0,MAX(0,B25-C25-H25)) -> 17534.143 | J25: =J24+G25 -> 1290.7028
A26: 25 | B26: =MAX(0,I25) -> 17534.143 | C26: =IF(B26<=0,0,IF(A26='Loan Calculator'!B12,MIN('Loan Calculator'!B11,B26),0)+IF(A26='Loan Calculator'!B14,MIN('Loan Calculator'!B13,B26),0)) -> 0 | D26: =IF(B26<=0,0,'Loan Calculator'!B4) -> 365.72 | E26: =IF(B26<=0,0,IF(A26>='Loan Calculator'!B18,'Loan Calculator'!B17,0)+IF(A26>='Loan Calculator'!B20,'Loan Calculator'!B19,0)+IF(A26>='Loan Calculator'!B22,'Loan Calculator'!B21,0)) -> 197.44 | F26: =IF(B26<=0,0,MIN(D26+E26,(B26-C26)*(1+'Loan Calculator'!B7))) -> 563.16 | G26: =IF(B26<=0,0,MAX(0,(B26-C26)*'Loan Calculator'!B7)) -> 40.463407 | H26: =IF(B26<=0,0,F26-G26) -> 522.69659 | I26: =IF(B26<=0,0,MAX(0,B26-C26-H26)) -> 17011.446 | J26: =J25+G26 -> 1331.1662
A27: 26 | B27: =MAX(0,I26) -> 17011.446 | C27: =IF(B27<=0,0,IF(A27='Loan Calculator'!B12,MIN('Loan Calculator'!B11,B27),0)+IF(A27='Loan Calculator'!B14,MIN('Loan Calculator'!B13,B27),0)) -> 0 | D27: =IF(B27<=0,0,'Loan Calculator'!B4) -> 365.72 | E27: =IF(B27<=0,0,IF(A27>='Loan Calculator'!B18,'Loan Calculator'!B17,0)+IF(A27>='Loan Calculator'!B20,'Loan Calculator'!B19,0)+IF(A27>='Loan Calculator'!B22,'Loan Calculator'!B21,0)) -> 197.44 | F27: =IF(B27<=0,0,MIN(D27+E27,(B27-C27)*(1+'Loan Calculator'!B7))) -> 563.16 | G27: =IF(B27<=0,0,MAX(0,(B27-C27)*'Loan Calculator'!B7)) -> 39.257184 | H27: =IF(B27<=0,0,F27-G27) -> 523.90282 | I27: =IF(B27<=0,0,MAX(0,B27-C27-H27)) -> 16487.543 | J27: =J26+G27 -> 1370.4234
A28: 27 | B28: =MAX(0,I27) -> 16487.543 | C28: =IF(B28<=0,0,IF(A28='Loan Calculator'!B12,MIN('Loan Calculator'!B11,B28),0)+IF(A28='Loan Calculator'!B14,MIN('Loan Calculator'!B13,B28),0)) -> 0 | D28: =IF(B28<=0,0,'Loan Calculator'!B4) -> 365.72 | E28: =IF(B28<=0,0,IF(A28>='Loan Calculator'!B18,'Loan Calculator'!B17,0)+IF(A28>='Loan Calculator'!B20,'Loan Calculator'!B19,0)+IF(A28>='Loan Calculator'!B22,'Loan Calculator'!B21,0)) -> 197.44 | F28: =IF(B28<=0,0,MIN(D28+E28,(B28-C28)*(1+'Loan Calculator'!B7))) -> 563.16 | G28: =IF(B28<=0,0,MAX(0,(B28-C28)*'Loan Calculator'!B7)) -> 38.048177 | H28: =IF(B28<=0,0,F28-G28) -> 525.11182 | I28: =IF(B28<=0,0,MAX(0,B28-C28-H28)) -> 15962.432 | J28: =J27+G28 -> 1408.4716
A29: 28 | B29: =MAX(0,I28) -> 15962.432 | C29: =IF(B29<=0,0,IF(A29='Loan Calculator'!B12,MIN('Loan Calculator'!B11,B29),0)+IF(A29='Loan Calculator'!B14,MIN('Loan Calculator'!B13,B29),0)) -> 0 | D29: =IF(B29<=0,0,'Loan Calculator'!B4) -> 365.72 | E29: =IF(B29<=0,0,IF(A29>='Loan Calculator'!B18,'Loan Calculator'!B17,0)+IF(A29>='Loan Calculator'!B20,'Loan Calculator'!B19,0)+IF(A29>='Loan Calculator'!B22,'Loan Calculator'!B21,0)) -> 197.44 | F29: =IF(B29<=0,0,MIN(D29+E29,(B29-C29)*(1+'Loan Calculator'!B7))) -> 563.16 | G29: =IF(B29<=0,0,MAX(0,(B29-C29)*'Loan Calculator'!B7)) -> 36.836381 | H29: =IF(B29<=0,0,F29-G29) -> 526.32362 | I29: =IF(B29<=0,0,MAX(0,B29-C29-H29)) -> 15436.108 | J29: =J28+G29 -> 1445.308
A30: 29 | B30: =MAX(0,I29) -> 15436.108 | C30: =IF(B30<=0,0,IF(A30='Loan Calculator'!B12,MIN('Loan Calculator'!B11,B30),0)+IF(A30='Loan Calculator'!B14,MIN('Loan Calculator'!B13,B30),0)) -> 0 | D30: =IF(B30<=0,0,'Loan Calculator'!B4) -> 365.72 | E30: =IF(B30<=0,0,IF(A30>='Loan Calculator'!B18,'Loan Calculator'!B17,0)+IF(A30>='Loan Calculator'!B20,'Loan Calculator'!B19,0)+IF(A30>='Loan Calculator'!B22,'Loan Calculator'!B21,0)) -> 197.44 | F30: =IF(B30<=0,0,MIN(D30+E30,(B30-C30)*(1+'Loan Calculator'!B7))) -> 563.16 | G30: =IF(B30<=0,0,MAX(0,(B30-C30)*'Loan Calculator'!B7)) -> 35.621788 | H30: =IF(B30<=0,0,F30-G30) -> 527.53821 | I30: =IF(B30<=0,0,MAX(0,B30-C30-H30)) -> 14908.57 | J30: =J29+G30 -> 1480.9298
A31: 30 | B31: =MAX(0,I30) -> 14908.57 | C31: =IF(B31<=0,0,IF(A31='Loan Calculator'!B12,MIN('Loan Calculator'!B11,B31),0)+IF(A31='Loan Calculator'!B14,MIN('Loan Calculator'!B13,B31),0)) -> 0 | D31: =IF(B31<=0,0,'Loan Calculator'!B4) -> 365.72 | E31: =IF(B31<=0,0,IF(A31>='Loan Calculator'!B18,'Loan Calculator'!B17,0)+IF(A31>='Loan Calculator'!B20,'Loan Calculator'!B19,0)+IF(A31>='Loan Calculator'!B22,'Loan Calculator'!B21,0)) -> 197.44 | F31: =IF(B31<=0,0,MIN(D31+E31,(B31-C31)*(1+'Loan Calculator'!B7))) -> 563.16 | G31: =IF(B31<=0,0,MAX(0,(B31-C31)*'Loan Calculator'!B7)) -> 34.404392 | H31: =IF(B31<=0,0,F31-G31) -> 528.75561 | I31: =IF(B31<=0,0,MAX(0,B31-C31-H31)) -> 14379.814 | J31: =J30+G31 -> 1515.3342
A32: 31 | B32: =MAX(0,I31) -> 14379.814 | C32: =IF(B32<=0,0,IF(A32='Loan Calculator'!B12,MIN('Loan Calculator'!B11,B32),0)+IF(A32='Loan Calculator'!B14,MIN('Loan Calculator'!B13,B32),0)) -> 0 | D32: =IF(B32<=0,0,'Loan Calculator'!B4) -> 365.72 | E32: =IF(B32<=0,0,IF(A32>='Loan Calculator'!B18,'Loan Calculator'!B17,0)+IF(A32>='Loan Calculator'!B20,'Loan Calculator'!B19,0)+IF(A32>='Loan Calculator'!B22,'Loan Calculator'!B21,0)) -> 197.44 | F32: =IF(B32<=0,0,MIN(D32+E32,(B32-C32)*(1+'Loan Calculator'!B7))) -> 563.16 | G32: =IF(B32<=0,0,MAX(0,(B32-C32)*'Loan Calculator'!B7)) -> 33.184187 | H32: =IF(B32<=0,0,F32-G32) -> 529.97581 | I32: =IF(B32<=0,0,MAX(0,B32-C32-H32)) -> 13849.838 | J32: =J31+G32 -> 1548.5183
A33: 32 | B33: =MAX(0,I32) -> 13849.838 | C33: =IF(B33<=0,0,IF(A33='Loan Calculator'!B12,MIN('Loan Calculator'!B11,B33),0)+IF(A33='Loan Calculator'!B14,MIN('Loan Calculator'!B13,B33),0)) -> 0 | D33: =IF(B33<=0,0,'Loan Calculator'!B4) -> 365.72 | E33: =IF(B33<=0,0,IF(A33>='Loan Calculator'!B18,'Loan Calculator'!B17,0)+IF(A33>='Loan Calculator'!B20,'Loan Calculator'!B19,0)+IF(A33>='Loan Calculator'!B22,'Loan Calculator'!B21,0)) -> 197.44 | F33: =IF(B33<=0,0,MIN(D33+E33,(B33-C33)*(1+'Loan Calculator'!B7))) -> 563.16 | G33: =IF(B33<=0,0,MAX(0,(B33-C33)*'Loan Calculator'!B7)) -> 31.961165 | H33: =IF(B33<=0,0,F33-G33) -> 531.19883 | I33: =IF(B33<=0,0,MAX(0,B33-C33-H33)) -> 13318.64 | J33: =J32+G33 -> 1580.4795
A34: 33 | B34: =MAX(0,I33) -> 13318.64 | C34: =IF(B34<=0,0,IF(A34='Loan Calculator'!B12,MIN('Loan Calculator'!B11,B34),0)+IF(A34='Loan Calculator'!B14,MIN('Loan Calculator'!B13,B34),0)) -> 0 | D34: =IF(B34<=0,0,'Loan Calculator'!B4) -> 365.72 | E34: =IF(B34<=0,0,IF(A34>='Loan Calculator'!B18,'Loan Calculator'!B17,0)+IF(A34>='Loan Calculator'!B20,'Loan Calculator'!B19,0)+IF(A34>='Loan Calculator'!B22,'Loan Calculator'!B21,0)) -> 197.44 | F34: =IF(B34<=0,0,MIN(D34+E34,(B34-C34)*(1+'Loan Calculator'!B7))) -> 563.16 | G34: =IF(B34<=0,0,MAX(0,(B34-C34)*'Loan Calculator'!B7)) -> 30.735322 | H34: =IF(B34<=0,0,F34-G34) -> 532.42468 | I34: =IF(B34<=0,0,MAX(0,B34-C34-H34)) -> 12786.215 | J34: =J33+G34 -> 1611.2148
A35: 34 | B35: =MAX(0,I34) -> 12786.215 | C35: =IF(B35<=0,0,IF(A35='Loan Calculator'!B12,MIN('Loan Calculator'!B11,B35),0)+IF(A35='Loan Calculator'!B14,MIN('Loan Calculator'!B13,B35),0)) -> 0 | D35: =IF(B35<=0,0,'Loan Calculator'!B4) -> 365.72 | E35: =IF(B35<=0,0,IF(A35>='Loan Calculator'!B18,'Loan Calculator'!B17,0)+IF(A35>='Loan Calculator'!B20,'Loan Calculator'!B19,0)+IF(A35>='Loan Calculator'!B22,'Loan Calculator'!B21,0)) -> 197.44 | F35: =IF(B35<=0,0,MIN(D35+E35,(B35-C35)*(1+'Loan Calculator'!B7))) -> 563.16 | G35: =IF(B35<=0,0,MAX(0,(B35-C35)*'Loan Calculator'!B7)) -> 29.50665 | H35: =IF(B35<=0,0,F35-G35) -> 533.65335 | I35: =IF(B35<=0,0,MAX(0,B35-C35-H35)) -> 12252.561 | J35: =J34+G35 -> 1640.7215
A36: 35 | B36: =MAX(0,I35) -> 12252.561 | C36: =IF(B36<=0,0,IF(A36='Loan Calculator'!B12,MIN('Loan Calculator'!B11,B36),0)+IF(A36='Loan Calculator'!B14,MIN('Loan Calculator'!B13,B36),0)) -> 0 | D36: =IF(B36<=0,0,'Loan Calculator'!B4) -> 365.72 | E36: =IF(B36<=0,0,IF(A36>='Loan Calculator'!B18,'Loan Calculator'!B17,0)+IF(A36>='Loan Calculator'!B20,'Loan Calculator'!B19,0)+IF(A36>='Loan Calculator'!B22,'Loan Calculator'!B21,0)) -> 197.44 | F36: =IF(B36<=0,0,MIN(D36+E36,(B36-C36)*(1+'Loan Calculator'!B7))) -> 563.16 | G36: =IF(B36<=0,0,MAX(0,(B36-C36)*'Loan Calculator'!B7)) -> 28.275142 | H36: =IF(B36<=0,0,F36-G36) -> 534.88486 | I36: =IF(B36<=0,0,MAX(0,B36-C36-H36)) -> 11717.677 | J36: =J35+G36 -> 1668.9966
A37: 36 | B37: =MAX(0,I36) -> 11717.677 | C37: =IF(B37<=0,0,IF(A37='Loan Calculator'!B12,MIN('Loan Calculator'!B11,B37),0)+IF(A37='Loan Calculator'!B14,MIN('Loan Calculator'!B13,B37),0)) -> 0 | D37: =IF(B37<=0,0,'Loan Calculator'!B4) -> 365.72 | E37: =IF(B37<=0,0,IF(A37>='Loan Calculator'!B18,'Loan Calculator'!B17,0)+IF(A37>='Loan Calculator'!B20,'Loan Calculator'!B19,0)+IF(A37>='Loan Calculator'!B22,'Loan Calculator'!B21,0)) -> 197.44 | F37: =IF(B37<=0,0,MIN(D37+E37,(B37-C37)*(1+'Loan Calculator'!B7))) -> 563.16 | G37: =IF(B37<=0,0,MAX(0,(B37-C37)*'Loan Calculator'!B7)) -> 27.040792 | H37: =IF(B37<=0,0,F37-G37) -> 536.11921 | I37: =IF(B37<=0,0,MAX(0,B37-C37-H37)) -> 11181.557 | J37: =J36+G37 -> 1696.0374
A38: 37 | B38: =MAX(0,I37) -> 11181.557 | C38: =IF(B38<=0,0,IF(A38='Loan Calculator'!B12,MIN('Loan Calculator'!B11,B38),0)+IF(A38='Loan Calculator'!B14,MIN('Loan Calculator'!B13,B38),0)) -> 0 | D38: =IF(B38<=0,0,'Loan Calculator'!B4) -> 365.72 | E38: =IF(B38<=0,0,IF(A38>='Loan Calculator'!B18,'Loan Calculator'!B17,0)+IF(A38>='Loan Calculator'!B20,'Loan Calculator'!B19,0)+IF(A38>='Loan Calculator'!B22,'Loan Calculator'!B21,0)) -> 197.44 | F38: =IF(B38<=0,0,MIN(D38+E38,(B38-C38)*(1+'Loan Calculator'!B7))) -> 563.16 | G38: =IF(B38<=0,0,MAX(0,(B38-C38)*'Loan Calculator'!B7)) -> 25.803594 | H38: =IF(B38<=0,0,F38-G38) -> 537.35641 | I38: =IF(B38<=0,0,MAX(0,B38-C38-H38)) -> 10644.201 | J38: =J37+G38 -> 1721.841
A39: 38 | B39: =MAX(0,I38) -> 10644.201 | C39: =IF(B39<=0,0,IF(A39='Loan Calculator'!B12,MIN('Loan Calculator'!B11,B39),0)+IF(A39='Loan Calculator'!B14,MIN('Loan Calculator'!B13,B39),0)) -> 0 | D39: =IF(B39<=0,0,'Loan Calculator'!B4) -> 365.72 | E39: =IF(B39<=0,0,IF(A39>='Loan Calculator'!B18,'Loan Calculator'!B17,0)+IF(A39>='Loan Calculator'!B20,'Loan Calculator'!B19,0)+IF(A39>='Loan Calculator'!B22,'Loan Calculator'!B21,0)) -> 197.44 | F39: =IF(B39<=0,0,MIN(D39+E39,(B39-C39)*(1+'Loan Calculator'!B7))) -> 563.16 | G39: =IF(B39<=0,0,MAX(0,(B39-C39)*'Loan Calculator'!B7)) -> 24.563541 | H39: =IF(B39<=0,0,F39-G39) -> 538.59646 | I39: =IF(B39<=0,0,MAX(0,B39-C39-H39)) -> 10105.605 | J39: =J38+G39 -> 1746.4045
A40: 39 | B40: =MAX(0,I39) -> 10105.605 | C40: =IF(B40<=0,0,IF(A40='Loan Calculator'!B12,MIN('Loan Calculator'!B11,B40),0)+IF(A40='Loan Calculator'!B14,MIN('Loan Calculator'!B13,B40),0)) -> 0 | D40: =IF(B40<=0,0,'Loan Calculator'!B4) -> 365.72 | E40: =IF(B40<=0,0,IF(A40>='Loan Calculator'!B18,'Loan Calculator'!B17,0)+IF(A40>='Loan Calculator'!B20,'Loan Calculator'!B19,0)+IF(A40>='Loan Calculator'!B22,'Loan Calculator'!B21,0)) -> 197.44 | F40: =IF(B40<=0,0,MIN(D40+E40,(B40-C40)*(1+'Loan Calculator'!B7))) -> 563.16 | G40: =IF(B40<=0,0,MAX(0,(B40-C40)*'Loan Calculator'!B7)) -> 23.320626 | H40: =IF(B40<=0,0,F40-G40) -> 539.83937 | I40: =IF(B40<=0,0,MAX(0,B40-C40-H40)) -> 9565.7652 | J40: =J39+G40 -> 1769.7252
...

Sheet Baseline
A1: Period | B1: Opening Balance | C1: Payment | D1: Interest | E1: Principal | F1: Closing Balance | G1: Cumulative Interest
A2: 1 | B2: ='Loan Calculator'!B2 -> 36890 | C2: =IF(B2<=0,0,MIN('Loan Calculator'!B4,B2*(1+'Loan Calculator'!B7))) -> 365.72 | D2: =IF(B2<=0,0,B2*'Loan Calculator'!B7) -> 85.130769 | E2: =IF(B2<=0,0,C2-D2) -> 280.58923 | F2: =IF(B2<=0,0,MAX(0,B2-E2)) -> 36609.411 | G2: =D2 -> 85.130769 | I2: Total Periods: | J2: =COUNTIF(B2:B201,">"&0) -> 115
A3: 2 | B3: =MAX(0,F2) -> 36609.411 | C3: =IF(B3<=0,0,MIN('Loan Calculator'!B4,B3*(1+'Loan Calculator'!B7))) -> 365.72 | D3: =IF(B3<=0,0,B3*'Loan Calculator'!B7) -> 84.483256 | E3: =IF(B3<=0,0,C3-D3) -> 281.23674 | F3: =IF(B3<=0,0,MAX(0,B3-E3)) -> 36328.174 | G3: =G2+D3 -> 169.61402 | I3: Total Interest: | J3: =SUM(D2:D201) -> 5151.5318
A4: 3 | B4: =MAX(0,F3) -> 36328.174 | C4: =IF(B4<=0,0,MIN('Loan Calculator'!B4,B4*(1+'Loan Calculator'!B7))) -> 365.72 | D4: =IF(B4<=0,0,B4*'Loan Calculator'!B7) -> 83.834248 | E4: =IF(B4<=0,0,C4-D4) -> 281.88575 | F4: =IF(B4<=0,0,MAX(0,B4-E4)) -> 36046.288 | G4: =G3+D4 -> 253.44827 | I4: Total Payments: | J4: =SUM(C2:C201) -> 42041.532
A5: 4 | B5: =MAX(0,F4) -> 36046.288 | C5: =IF(B5<=0,0,MIN('Loan Calculator'!B4,B5*(1+'Loan Calculator'!B7))) -> 365.72 | D5: =IF(B5<=0,0,B5*'Loan Calculator'!B7) -> 83.183742 | E5: =IF(B5<=0,0,C5-D5) -> 282.53626 | F5: =IF(B5<=0,0,MAX(0,B5-E5)) -> 35763.752 | G5: =G4+D5 -> 336.63201
A6: 5 | B6: =MAX(0,F5) -> 35763.752 | C6: =IF(B6<=0,0,MIN('Loan Calculator'!B4,B6*(1+'Loan Calculator'!B7))) -> 365.72 | D6: =IF(B6<=0,0,B6*'Loan Calculator'!B7) -> 82.531735 | E6: =IF(B6<=0,0,C6-D6) -> 283.18826 | F6: =IF(B6<=0,0,MAX(0,B6-E6)) -> 35480.564 | G6: =G5+D6 -> 419.16375
A7: 6 | B7: =MAX(0,F6) -> 35480.564 | C7: =IF(B7<=0,0,MIN('Loan Calculator'!B4,B7*(1+'Loan Calculator'!B7))) -> 365.72 | D7: =IF(B7<=0,0,B7*'Loan Calculator'!B7) -> 81.878224 | E7: =IF(B7<=0,0,C7-D7) -> 283.84178 | F7: =IF(B7<=0,0,MAX(0,B7-E7)) -> 35196.722 | G7: =G6+D7 -> 501.04197
A8: 7 | B8: =MAX(0,F7) -> 35196.722 | C8: =IF(B8<=0,0,MIN('Loan Calculator'!B4,B8*(1+'Loan Calculator'!B7))) -> 365.72 | D8: =IF(B8<=0,0,B8*'Loan Calculator'!B7) -> 81.223205 | E8: =IF(B8<=0,0,C8-D8) -> 284.4968 | F8: =IF(B8<=0,0,MAX(0,B8-E8)) -> 34912.225 | G8: =G7+D8 -> 582.26518
A9: 8 | B9: =MAX(0,F8) -> 34912.225 | C9: =IF(B9<=0,0,MIN('Loan Calculator'!B4,B9*(1+'Loan Calculator'!B7))) -> 365.72 | D9: =IF(B9<=0,0,B9*'Loan Calculator'!B7) -> 80.566673 | E9: =IF(B9<=0,0,C9-D9) -> 285.15333 | F9: =IF(B9<=0,0,MAX(0,B9-E9)) -> 34627.072 | G9: =G8+D9 -> 662.83185
A10: 9 | B10: =MAX(0,F9) -> 34627.072 | C10: =IF(B10<=0,0,MIN('Loan Calculator'!B4,B10*(1+'Loan Calculator'!B7))) -> 365.72 | D10: =IF(B10<=0,0,B10*'Loan Calculator'!B7) -> 79.908627 | E10: =IF(B10<=0,0,C10-D10) -> 285.81137 | F10: =IF(B10<=0,0,MAX(0,B10-E10)) -> 34341.26 | G10: =G9+D10 -> 742.74048
A11: 10 | B11: =MAX(0,F10) -> 34341.26 | C11: =IF(B11<=0,0,MIN('Loan Calculator'!B4,B11*(1+'Loan Calculator'!B7))) -> 365.72 | D11: =IF(B11<=0,0,B11*'Loan Calculator'!B7) -> 79.249063 | E11: =IF(B11<=0,0,C11-D11) -> 286.47094 | F11: =IF(B11<=0,0,MAX(0,B11-E11)) -> 34054.79 | G11: =G10+D11 -> 821.98954
A12: 11 | B12: =MAX(0,F11) -> 34054.79 | C12: =IF(B12<=0,0,MIN('Loan Calculator'!B4,B12*(1+'Loan Calculator'!B7))) -> 365.72 | D12: =IF(B12<=0,0,B12*'Loan Calculator'!B7) -> 78.587976 | E12: =IF(B12<=0,0,C12-D12) -> 287.13202 | F12: =IF(B12<=0,0,MAX(0,B12-E12)) -> 33767.658 | G12: =G11+D12 -> 900.57752
A13: 12 | B13: =MAX(0,F12) -> 33767.658 | C13: =IF(B13<=0,0,MIN('Loan Calculator'!B4,B13*(1+'Loan Calculator'!B7))) -> 365.72 | D13: =IF(B13<=0,0,B13*'Loan Calculator'!B7) -> 77.925364 | E13: =IF(B13<=0,0,C13-D13) -> 287.79464 | F13: =IF(B13<=0,0,MAX(0,B13-E13)) -> 33479.863 | G13: =G12+D13 -> 978.50288
A14: 13 | B14: =MAX(0,F13) -> 33479.863 | C14: =IF(B14<=0,0,MIN('Loan Calculator'!B4,B14*(1+'Loan Calculator'!B7))) -> 365.72 | D14: =IF(B14<=0,0,B14*'Loan Calculator'!B7) -> 77.261222 | E14: =IF(B14<=0,0,C14-D14) -> 288.45878 | F14: =IF(B14<=0,0,MAX(0,B14-E14)) -> 33191.404 | G14: =G13+D14 -> 1055.7641
A15: 14 | B15: =MAX(0,F14) -> 33191.404 | C15: =IF(B15<=0,0,MIN('Loan Calculator'!B4,B15*(1+'Loan Calculator'!B7))) -> 365.72 | D15: =IF(B15<=0,0,B15*'Loan Calculator'!B7) -> 76.595548 | E15: =IF(B15<=0,0,C15-D15) -> 289.12445 | F15: =IF(B15<=0,0,MAX(0,B15-E15)) -> 32902.28 | G15: =G14+D15 -> 1132.3597
A16: 15 | B16: =MAX(0,F15) -> 32902.28 | C16: =IF(B16<=0,0,MIN('Loan Calculator'!B4,B16*(1+'Loan Calculator'!B7))) -> 365.72 | D16: =IF(B16<=0,0,B16*'Loan Calculator'!B7) -> 75.928338 | E16: =IF(B16<=0,0,C16-D16) -> 289.79166 | F16: =IF(B16<=0,0,MAX(0,B16-E16)) -> 32612.488 | G16: =G15+D16 -> 1208.288
A17: 16 | B17: =MAX(0,F16) -> 32612.488 | C17: =IF(B17<=0,0,MIN('Loan Calculator'!B4,B17*(1+'Loan Calculator'!B7))) -> 365.72 | D17: =IF(B17<=0,0,B17*'Loan Calculator'!B7) -> 75.259588 | E17: =IF(B17<=0,0,C17-D17) -> 290.46041 | F17: =IF(B17<=0,0,MAX(0,B17-E17)) -> 32322.028 | G17: =G16+D17 -> 1283.5476
A18: 17 | B18: =MAX(0,F17) -> 32322.028 | C18: =IF(B18<=0,0,MIN('Loan Calculator'!B4,B18*(1+'Loan Calculator'!B7))) -> 365.72 | D18: =IF(B18<=0,0,B18*'Loan Calculator'!B7) -> 74.589294 | E18: =IF(B18<=0,0,C18-D18) -> 291.13071 | F18: =IF(B18<=0,0,MAX(0,B18-E18)) -> 32030.897 | G18: =G17+D18 -> 1358.1369
A19: 18 | B19: =MAX(0,F18) -> 32030.897 | C19: =IF(B19<=0,0,MIN('Loan Calculator'!B4,B19*(1+'Loan Calculator'!B7))) -> 365.72 | D19: =IF(B19<=0,0,B19*'Loan Calculator'!B7) -> 73.917454 | E19: =IF(B19<=0,0,C19-D19) -> 291.80255 | F19: =IF(B19<=0,0,MAX(0,B19-E19)) -> 31739.094 | G19: =G18+D19 -> 1432.0543
A20: 19 | B20: =MAX(0,F19) -> 31739.094 | C20: =IF(B20<=0,0,MIN('Loan Calculator'!B4,B20*(1+'Loan Calculator'!B7))) -> 365.72 | D20: =IF(B20<=0,0,B20*'Loan Calculator'!B7) -> 73.244064 | E20: =IF(B20<=0,0,C20-D20) -> 292.47594 | F20: =IF(B20<=0,0,MAX(0,B20-E20)) -> 31446.618 | G20: =G19+D20 -> 1505.2984
A21: 20 | B21: =MAX(0,F20) -> 31446.618 | C21: =IF(B21<=0,0,MIN('Loan Calculator'!B4,B21*(1+'Loan Calculator'!B7))) -> 365.72 | D21: =IF(B21<=0,0,B21*'Loan Calculator'!B7) -> 72.569119 | E21: =IF(B21<=0,0,C21-D21) -> 293.15088 | F21: =IF(B21<=0,0,MAX(0,B21-E21)) -> 31153.468 | G21: =G20+D21 -> 1577.8675
A22: 21 | B22: =MAX(0,F21) -> 31153.468 | C22: =IF(B22<=0,0,MIN('Loan Calculator'!B4,B22*(1+'Loan Calculator'!B7))) -> 365.72 | D22: =IF(B22<=0,0,B22*'Loan Calculator'!B7) -> 71.892617 | E22: =IF(B22<=0,0,C22-D22) -> 293.82738 | F22: =IF(B22<=0,0,MAX(0,B22-E22)) -> 30859.64 | G22: =G21+D22 -> 1649.7601
A23: 22 | B23: =MAX(0,F22) -> 30859.64 | C23: =IF(B23<=0,0,MIN('Loan Calculator'!B4,B23*(1+'Loan Calculator'!B7))) -> 365.72 | D23: =IF(B23<=0,0,B23*'Loan Calculator'!B7) -> 71.214554 | E23: =IF(B23<=0,0,C23-D23) -> 294.50545 | F23: =IF(B23<=0,0,MAX(0,B23-E23)) -> 30565.135 | G23: =G22+D23 -> 1720.9747
A24: 23 | B24: =MAX(0,F23) -> 30565.135 | C24: =IF(B24<=0,0,MIN('Loan Calculator'!B4,B24*(1+'Loan Calculator'!B7))) -> 365.72 | D24: =IF(B24<=0,0,B24*'Loan Calculator'!B7) -> 70.534926 | E24: =IF(B24<=0,0,C24-D24) -> 295.18507 | F24: =IF(B24<=0,0,MAX(0,B24-E24)) -> 30269.95 | G24: =G23+D24 -> 1791.5096
A25: 24 | B25: =MAX(0,F24) -> 30269.95 | C25: =IF(B25<=0,0,MIN('Loan Calculator'!B4,B25*(1+'Loan Calculator'!B7))) -> 365.72 | D25: =IF(B25<=0,0,B25*'Loan Calculator'!B7) -> 69.85373 | E25: =IF(B25<=0,0,C25-D25) -> 295.86627 | F25: =IF(B25<=0,0,MAX(0,B25-E25)) -> 29974.083 | G25: =G24+D25 -> 1861.3633
A26: 25 | B26: =MAX(0,F25) -> 29974.083 | C26: =IF(B26<=0,0,MIN('Loan Calculator'!B4,B26*(1+'Loan Calculator'!B7))) -> 365.72 | D26: =IF(B26<=0,0,B26*'Loan Calculator'!B7) -> 69.170962 | E26: =IF(B26<=0,0,C26-D26) -> 296.54904 | F26: =IF(B26<=0,0,MAX(0,B26-E26)) -> 29677.534 | G26: =G25+D26 -> 1930.5343
A27: 26 | B27: =MAX(0,F26) -> 29677.534 | C27: =IF(B27<=0,0,MIN('Loan Calculator'!B4,B27*(1+'Loan Calculator'!B7))) -> 365.72 | D27: =IF(B27<=0,0,B27*'Loan Calculator'!B7) -> 68.486618 | E27: =IF(B27<=0,0,C27-D27) -> 297.23338 | F27: =IF(B27<=0,0,MAX(0,B27-E27)) -> 29380.301 | G27: =G26+D27 -> 1999.0209
A28: 27 | B28: =MAX(0,F27) -> 29380.301 | C28: =IF(B28<=0,0,MIN('Loan Calculator'!B4,B28*(1+'Loan Calculator'!B7))) -> 365.72 | D28: =IF(B28<=0,0,B28*'Loan Calculator'!B7) -> 67.800694 | E28: =IF(B28<=0,0,C28-D28) -> 297.91931 | F28: =IF(B28<=0,0,MAX(0,B28-E28)) -> 29082.382 | G28: =G27+D28 -> 2066.8216
A29: 28 | B29: =MAX(0,F28) -> 29082.382 | C29: =IF(B29<=0,0,MIN('Loan Calculator'!B4,B29*(1+'Loan Calculator'!B7))) -> 365.72 | D29: =IF(B29<=0,0,B29*'Loan Calculator'!B7) -> 67.113188 | E29: =IF(B29<=0,0,C29-D29) -> 298.60681 | F29: =IF(B29<=0,0,MAX(0,B29-E29)) -> 28783.775 | G29: =G28+D29 -> 2133.9348
A30: 29 | B30: =MAX(0,F29) -> 28783.775 | C30: =IF(B30<=0,0,MIN('Loan Calculator'!B4,B30*(1+'Loan Calculator'!B7))) -> 365.72 | D30: =IF(B30<=0,0,B30*'Loan Calculator'!B7) -> 66.424096 | E30: =IF(B30<=0,0,C30-D30) -> 299.2959 | F30: =IF(B30<=0,0,MAX(0,B30-E30)) -> 28484.479 | G30: =G29+D30 -> 2200.3589
A31: 30 | B31: =MAX(0,F30) -> 28484.479 | C31: =IF(B31<=0,0,MIN('Loan Calculator'!B4,B31*(1+'Loan Calculator'!B7))) -> 365.72 | D31: =IF(B31<=0,0,B31*'Loan Calculator'!B7) -> 65.733413 | E31: =IF(B31<=0,0,C31-D31) -> 299.98659 | F31: =IF(B31<=0,0,MAX(0,B31-E31)) -> 28184.492 | G31: =G30+D31 -> 2266.0923
A32: 31 | B32: =MAX(0,F31) -> 28184.492 | C32: =IF(B32<=0,0,MIN('Loan Calculator'!B4,B32*(1+'Loan Calculator'!B7))) -> 365.72 | D32: =IF(B32<=0,0,B32*'Loan Calculator'!B7) -> 65.041136 | E32: =IF(B32<=0,0,C32-D32) -> 300.67886 | F32: =IF(B32<=0,0,MAX(0,B32-E32)) -> 27883.813 | G32: =G31+D32 -> 2331.1334
A33: 32 | B33: =MAX(0,F32) -> 27883.813 | C33: =IF(B33<=0,0,MIN('Loan Calculator'!B4,B33*(1+'Loan Calculator'!B7))) -> 365.72 | D33: =IF(B33<=0,0,B33*'Loan Calculator'!B7) -> 64.347262 | E33: =IF(B33<=0,0,C33-D33) -> 301.37274 | F33: =IF(B33<=0,0,MAX(0,B33-E33)) -> 27582.441 | G33: =G32+D33 -> 2395.4807
A34: 33 | B34: =MAX(0,F33) -> 27582.441 | C34: =IF(B34<=0,0,MIN('Loan Calculator'!B4,B34*(1+'Loan Calculator'!B7))) -> 365.72 | D34: =IF(B34<=0,0,B34*'Loan Calculator'!B7) -> 63.651786 | E34: =IF(B34<=0,0,C34-D34) -> 302.06821 | F34: =IF(B34<=0,0,MAX(0,B34-E34)) -> 27280.372 | G34: =G33+D34 -> 2459.1325
A35: 34 | B35: =MAX(0,F34) -> 27280.372 | C35: =IF(B35<=0,0,MIN('Loan Calculator'!B4,B35*(1+'Loan Calculator'!B7))) -> 365.72 | D35: =IF(B35<=0,0,B35*'Loan Calculator'!B7) -> 62.954706 | E35: =IF(B35<=0,0,C35-D35) -> 302.76529 | F35: =IF(B35<=0,0,MAX(0,B35-E35)) -> 26977.607 | G35: =G34+D35 -> 2522.0872
A36: 35 | B36: =MAX(0,F35) -> 26977.607 | C36: =IF(B36<=0,0,MIN('Loan Calculator'!B4,B36*(1+'Loan Calculator'!B7))) -> 365.72 | D36: =IF(B36<=0,0,B36*'Loan Calculator'!B7) -> 62.256017 | E36: =IF(B36<=0,0,C36-D36) -> 303.46398 | F36: =IF(B36<=0,0,MAX(0,B36-E36)) -> 26674.143 | G36: =G35+D36 -> 2584.3432
A37: 36 | B37: =MAX(0,F36) -> 26674.143 | C37: =IF(B37<=0,0,MIN('Loan Calculator'!B4,B37*(1+'Loan Calculator'!B7))) -> 365.72 | D37: =IF(B37<=0,0,B37*'Loan Calculator'!B7) -> 61.555715 | E37: =IF(B37<=0,0,C37-D37) -> 304.16428 | F37: =IF(B37<=0,0,MAX(0,B37-E37)) -> 26369.979 | G37: =G36+D37 -> 2645.8989
A38: 37 | B38: =MAX(0,F37) -> 26369.979 | C38: =IF(B38<=0,0,MIN('Loan Calculator'!B4,B38*(1+'Loan Calculator'!B7))) -> 365.72 | D38: =IF(B38<=0,0,B38*'Loan Calculator'!B7) -> 60.853798 | E38: =IF(B38<=0,0,C38-D38) -> 304.8662 | F38: =IF(B38<=0,0,MAX(0,B38-E38)) -> 26065.113 | G38: =G37+D38 -> 2706.7527
A39: 38 | B39: =MAX(0,F38) -> 26065.113 | C39: =IF(B39<=0,0,MIN('Loan Calculator'!B4,B39*(1+'Loan Calculator'!B7))) -> 365.72 | D39: =IF(B39<=0,0,B39*'Loan Calculator'!B7) -> 60.15026 | E39: =IF(B39<=0,0,C39-D39) -> 305.56974 | F39: =IF(B39<=0,0,MAX(0,B39-E39)) -> 25759.543 | G39: =G38+D39 -> 2766.903
A40: 39 | B40: =MAX(0,F39) -> 25759.543 | C40: =IF(B40<=0,0,MIN('Loan Calculator'!B4,B40*(1+'Loan Calculator'!B7))) -> 365.72 | D40: =IF(B40<=0,0,B40*'Loan Calculator'!B7) -> 59.445099 | E40: =IF(B40<=0,0,C40-D40) -> 306.2749 | F40: =IF(B40<=0,0,MAX(0,B40-E40)) -> 25453.268 | G40: =G39+D40 -> 2826.3481
...
